<?xml version="1.0"?>
<robot name="E:/Webots_Projects/JaniBot/Robot.urdf" xmlns:xacro="http://ros.org/wiki/xacro">
  <link name="base_link">
    <visual>
      <origin xyz="0 0 -0.065" rpy="0 0 0"/>
      <geometry>
        <box size="0.64 0.706849 0.4004"/>
      </geometry>
    </visual>
    <collision>
      <origin xyz="0 0 -0.065" rpy="0 0 0"/>
      <geometry>
        <box size="0.64 0.706849 0.4004"/>
      </geometry>
    </collision>
  </link>
  <joint name="base_motor" type="continuous">
    <parent link="base_link"/>
    <child link="base_motor_14"/>
    <axis xyz="0 0 1"/>
    <limit effort="10" velocity="10"/>
    <origin xyz="0 -0.2 0.13" rpy="0 0 0"/>
  </joint>
  <link name="base_motor_14">
    <visual>
      <origin xyz="0.0151996 1.11759e-08 0.204925" rpy="0 0 0"/>
      <geometry>
        <box size="0.129851 0.1 0.40393"/>
      </geometry>
    </visual>
    <collision>
      <origin xyz="0.0151996 1.11759e-08 0.204925" rpy="0 0 0"/>
      <geometry>
        <box size="0.129851 0.1 0.40393"/>
      </geometry>
    </collision>
  </link>
  <joint name="arm_a_motor" type="continuous">
    <parent link="base_motor_14"/>
    <child link="arm_a_motor_24"/>
    <axis xyz="1 0 0"/>
    <limit effort="10" velocity="10"/>
    <origin xyz="0.0801831 5.96046e-08 0.32689" rpy="0 0 0"/>
  </joint>
  <link name="arm_a_motor_24">
    <visual>
      <origin xyz="0.07 -0.176146 -1.86265e-08" rpy="0 0 0"/>
      <geometry>
        <box size="0.14 0.451743 0.1"/>
      </geometry>
    </visual>
    <collision>
      <origin xyz="0.07 -0.176146 -1.86265e-08" rpy="0 0 0"/>
      <geometry>
        <box size="0.14 0.451743 0.1"/>
      </geometry>
    </collision>
  </link>
  <joint name="joint_a_motor" type="continuous">
    <parent link="arm_a_motor_24"/>
    <child link="joint_a_motor_34"/>
    <axis xyz="0 1 0"/>
    <limit effort="10" velocity="10"/>
    <origin xyz="0.0798171 -0.399875 -5.96046e-08" rpy="0 0 0"/>
  </joint>
  <link name="joint_a_motor_34">
    <visual>
      <origin xyz="0.00113802 -0.0649255 0" rpy="0 0 0"/>
      <geometry>
        <box size="0.118092 0.129851 0.1"/>
      </geometry>
    </visual>
    <collision>
      <origin xyz="0.00113802 -0.0649255 0" rpy="0 0 0"/>
      <geometry>
        <box size="0.118092 0.129851 0.1"/>
      </geometry>
    </collision>
  </link>
  <joint name="arm_b_motor" type="continuous">
    <parent link="joint_a_motor_34"/>
    <child link="arm_b_motor_44"/>
    <axis xyz="1 0 0"/>
    <limit effort="10" velocity="10"/>
    <origin xyz="-0.057908 -0.080125 0" rpy="0 0 0"/>
  </joint>
  <link name="arm_b_motor_44">
    <visual>
      <origin xyz="-0.056334 -0.154057 9.31323e-09" rpy="0 0 0"/>
      <geometry>
        <box size="0.112668 0.408113 0.099452"/>
      </geometry>
    </visual>
    <collision>
      <origin xyz="-0.056334 -0.154057 9.31323e-09" rpy="0 0 0"/>
      <geometry>
        <box size="0.112668 0.408113 0.099452"/>
      </geometry>
    </collision>
  </link>
  <joint name="joint_b_motor" type="continuous">
    <parent link="arm_b_motor_44"/>
    <child link="joint_b_motor_54"/>
    <axis xyz="0 1 0"/>
    <limit effort="10" velocity="10"/>
    <origin xyz="-0.0626679 -0.358113 -5.96046e-08" rpy="0 0 0"/>
  </joint>
  <link name="joint_b_motor_54">
    <visual>
      <origin xyz="0.00990802 -0.0649255 -3.72529e-09" rpy="0 0 0"/>
      <geometry>
        <box size="0.140184 0.129851 0.1"/>
      </geometry>
    </visual>
    <collision>
      <origin xyz="0.00990802 -0.0649255 -3.72529e-09" rpy="0 0 0"/>
      <geometry>
        <box size="0.140184 0.129851 0.1"/>
      </geometry>
    </collision>
  </link>
  <joint name="joint_c_motor" type="continuous">
    <parent link="joint_b_motor_54"/>
    <child link="joint_c_motor_64"/>
    <axis xyz="1 0 0"/>
    <limit effort="10" velocity="10"/>
    <origin xyz="-0.05992 -0.080065 0" rpy="0 0 0"/>
  </joint>
  <link name="joint_c_motor_64">
    <visual>
      <origin xyz="-0.0649255 -2.23517e-08 0.00990805" rpy="0 0 0"/>
      <geometry>
        <box size="0.129851 0.1 0.140184"/>
      </geometry>
    </visual>
    <collision>
      <origin xyz="-0.0649255 -2.23517e-08 0.00990805" rpy="0 0 0"/>
      <geometry>
        <box size="0.129851 0.1 0.140184"/>
      </geometry>
    </collision>
  </link>
  <joint name="joint_d_motor" type="continuous">
    <parent link="joint_c_motor_64"/>
    <child link="joint_d_motor_74"/>
    <axis xyz="0 0 1"/>
    <limit effort="10" velocity="10"/>
    <origin xyz="-0.079971 0.000211835 0.08" rpy="0 0 0"/>
  </joint>
  <link name="joint_d_motor_74">
    <visual>
      <origin xyz="6.33299e-08 -0.0458905 0.0649255" rpy="0 0 0"/>
      <geometry>
        <box size="0.1 0.212149 0.129851"/>
      </geometry>
    </visual>
    <collision>
      <origin xyz="6.33299e-08 -0.0458905 0.0649255" rpy="0 0 0"/>
      <geometry>
        <box size="0.1 0.212149 0.129851"/>
      </geometry>
    </collision>
  </link>
  <joint name="grip_base_motor" type="continuous">
    <parent link="joint_d_motor_74"/>
    <child link="grip_base_motor_84"/>
    <axis xyz="0 1 0"/>
    <limit effort="10" velocity="10"/>
    <origin xyz="9.68575e-08 -0.160421 0.080125" rpy="0 0 0"/>
  </joint>
  <link name="grip_base_motor_84">
    <visual>
      <origin xyz="0.000149999 0 0" rpy="0 0 0"/>
      <geometry>
        <box size="0.159496 0.0262681 0.163764"/>
      </geometry>
    </visual>
    <collision>
      <origin xyz="0.000149999 0 0" rpy="0 0 0"/>
      <geometry>
        <box size="0.159496 0.0262681 0.163764"/>
      </geometry>
    </collision>
  </link>
  <joint name="grip_b_motor" type="continuous">
    <parent link="grip_base_motor_84"/>
    <child link="grip_b_motor_124"/>
    <axis xyz="0 0 1"/>
    <limit effort="10" velocity="10"/>
    <origin xyz="-0.06575 0.00192595 -5.96046e-08" rpy="0 0 0"/>
  </joint>
  <link name="grip_b_motor_124">
    <visual>
      <origin xyz="0.019878 -0.0818821 5.12227e-09" rpy="0 0 0"/>
      <geometry>
        <box size="0.0660241 0.163764 0.02467"/>
      </geometry>
    </visual>
    <collision>
      <origin xyz="0.019878 -0.0818821 5.12227e-09" rpy="0 0 0"/>
      <geometry>
        <box size="0.0660241 0.163764 0.02467"/>
      </geometry>
    </collision>
  </link>
  <joint name="grip_a_motor" type="continuous">
    <parent link="grip_base_motor_84"/>
    <child link="grip_a_motor_114"/>
    <axis xyz="0 0 1"/>
    <limit effort="10" velocity="10"/>
    <origin xyz="0.0656731 0.00192595 -5.96046e-08" rpy="0 0 0"/>
  </joint>
  <link name="grip_a_motor_114">
    <visual>
      <origin xyz="-0.019878 -0.0818821 1.86265e-08" rpy="0 0 0"/>
      <geometry>
        <box size="0.066024 0.163764 0.0246701"/>
      </geometry>
    </visual>
    <collision>
      <origin xyz="-0.019878 -0.0818821 1.86265e-08" rpy="0 0 0"/>
      <geometry>
        <box size="0.066024 0.163764 0.0246701"/>
      </geometry>
    </collision>
  </link>
  <joint name="grip_c_motor" type="continuous">
    <parent link="grip_base_motor_84"/>
    <child link="grip_c_motor_104"/>
    <axis xyz="1 0 0"/>
    <limit effort="10" velocity="10"/>
    <origin xyz="5.21541e-08 0.00192595 0.0657499" rpy="0 0 0"/>
  </joint>
  <link name="grip_c_motor_104">
    <visual>
      <origin xyz="2.56114e-08 -0.0818821 -0.019878" rpy="0 0 0"/>
      <geometry>
        <box size="0.0246701 0.163764 0.0660241"/>
      </geometry>
    </visual>
    <collision>
      <origin xyz="2.56114e-08 -0.0818821 -0.019878" rpy="0 0 0"/>
      <geometry>
        <box size="0.0246701 0.163764 0.0660241"/>
      </geometry>
    </collision>
  </link>
  <joint name="grip_d_motor" type="continuous">
    <parent link="grip_base_motor_84"/>
    <child link="grip_d_motor_94"/>
    <axis xyz="1 0 0"/>
    <limit effort="10" velocity="10"/>
    <origin xyz="-1.49012e-08 0.00192595 -0.0656731" rpy="0 0 0"/>
  </joint>
  <link name="grip_d_motor_94">
    <visual>
      <origin xyz="4.19095e-08 -0.0818821 0.019878" rpy="0 0 0"/>
      <geometry>
        <box size="0.0246701 0.163764 0.0660241"/>
      </geometry>
    </visual>
    <collision>
      <origin xyz="4.19095e-08 -0.0818821 0.019878" rpy="0 0 0"/>
      <geometry>
        <box size="0.0246701 0.163764 0.0660241"/>
      </geometry>
    </collision>
  </link>
</robot>
