#VRML_SIM R2021a utf8
WorldInfo {
  basicTimeStep 16
  coordinateSystem "NUE"
}
Viewpoint {
  orientation 0.5593475722087522 0.8089995144015609 0.18069332904734817 5.25800262080935
  position -1.3768677491546137 2.2976895176904093 1.8011472782757025
  follow "robot"
}
TexturedBackground {
  skybox FALSE
}
TexturedBackgroundLight {
}
Floor {
  tileSize 1 1
  appearance Parquetry {
    type "chequered"
    IBLStrength 0
  }
}
Robot {
  translation 0 0.2 0
  children [
    Robot {
      translation 0.07 0.05 0.06
      children [
        HingeJoint {
          jointParameters HingeJointParameters {
            axis 0 1 0
            anchor 0 0.055 0
          }
          device [
            RotationalMotor {
              name "motor1"
            }
          ]
          endPoint Solid {
            translation 0 0.055 0
            children [
              HingeJoint {
                jointParameters HingeJointParameters {
                  anchor -0.058 0 0
                }
                device [
                  RotationalMotor {
                    name "motor2"
                  }
                ]
                endPoint Solid {
                  translation -0.058 0 0
                  rotation 0 0 1 1.5708
                  children [
                    Solid {
                      translation 0 0 -0.24
                      children [
                        Shape {
                          appearance PBRAppearance {
                            baseColor 0.337255 0.337255 0.337255
                            roughness 1
                            metalness 0
                          }
                          geometry Box {
                            size 0.03 0.03 0.5
                          }
                        }
                      ]
                    }
                    Shape {
                      appearance PBRAppearance {
                        roughness 1
                        metalness 0
                      }
                      geometry Cylinder {
                        height 0.05
                        radius 0.03
                      }
                    }
                  ]
                }
              }
              Shape {
                appearance PBRAppearance {
                  roughness 1
                  metalness 0
                }
                geometry Cylinder {
                  height 0.05
                  radius 0.03
                }
              }
            ]
          }
        }
        DEF BASE Shape {
          appearance PBRAppearance {
            baseColor 0.180392 0.180392 0.180392
            roughness 1
            metalness 0
          }
          geometry Cylinder {
            height 0.05
            radius 0.03
          }
        }
      ]
      name "arm"
      controller ""
    }
    HingeJoint {
      jointParameters HingeJointParameters {
        anchor 0.125 -0.03 0.06
      }
      device [
        RotationalMotor {
          name "wheel_1"
        }
      ]
      endPoint DEF WHEEL_1 Solid {
        translation 0.125 -0.03 0.06
        rotation -4.0349041800631195e-11 4.0349190011209667e-11 1 1.5708
        children [
          DEF WHEEL Shape {
            appearance PBRAppearance {
              baseColorMap ImageTexture {
                url [
                  "textures/checkered_marble.jpg"
                ]
              }
              roughness 1
              metalness 0
            }
            geometry Cylinder {
              height 0.04
              radius 0.05
            }
          }
        ]
        boundingObject USE WHEEL
        physics DEF WHEEL_PH Physics {
        }
      }
    }
    HingeJoint {
      jointParameters HingeJointParameters {
        anchor 0.125 -0.03 -0.06
      }
      device [
        RotationalMotor {
          name "wheel_2"
        }
      ]
      endPoint DEF WHEEL_1 Solid {
        translation 0.125 -0.03 -0.06
        rotation -1.3459546076919104e-11 1.3459595516683245e-11 1 1.5708
        children [
          DEF WHEEL Shape {
            appearance PBRAppearance {
              baseColorMap ImageTexture {
                url [
                  "textures/checkered_marble.jpg"
                ]
              }
              roughness 1
              metalness 0
            }
            geometry Cylinder {
              height 0.04
              radius 0.05
            }
          }
        ]
        name "solid(2)"
        boundingObject USE WHEEL
        physics DEF WHEEL_PH Physics {
        }
      }
    }
    HingeJoint {
      jointParameters HingeJointParameters {
        anchor -0.125 -0.03 0.06
      }
      device [
        RotationalMotor {
          name "wheel_3"
        }
      ]
      endPoint DEF WHEEL_2 Solid {
        translation -0.125 -0.03 0.06
        rotation -4.0349202845529695e-11 4.0349351056699704e-11 1 1.5708
        children [
          DEF WHEEL Shape {
            appearance PBRAppearance {
              baseColorMap ImageTexture {
                url [
                  "textures/checkered_marble.jpg"
                ]
              }
              roughness 1
              metalness 0
            }
            geometry Cylinder {
              height 0.04
              radius 0.05
            }
          }
        ]
        name "solid(1)"
        boundingObject USE WHEEL
        physics DEF WHEEL_PH Physics {
        }
      }
    }
    HingeJoint {
      jointParameters HingeJointParameters {
        anchor -0.125 -0.03 -0.06
      }
      device [
        RotationalMotor {
          name "wheel_4"
        }
      ]
      endPoint DEF WHEEL_2 Solid {
        translation -0.125 -0.03 -0.06
        rotation -4.034964378667725e-11 4.0349791999466925e-11 1 1.5708
        children [
          DEF WHEEL Shape {
            appearance PBRAppearance {
              baseColorMap ImageTexture {
                url [
                  "textures/checkered_marble.jpg"
                ]
              }
              roughness 1
              metalness 0
            }
            geometry Cylinder {
              height 0.04
              radius 0.05
            }
          }
        ]
        name "solid(3)"
        boundingObject USE WHEEL
        physics DEF WHEEL_PH Physics {
        }
      }
    }
    DEF BODY Shape {
      appearance PBRAppearance {
        baseColor 1 0.654902 0.101961
        roughness 1
        metalness 0
      }
      geometry Box {
        size 0.2 0.1 0.2
      }
    }
  ]
  boundingObject USE BODY
  physics Physics {
  }
  controller ""
}
