<?xml version="1.0" ?>
<!-- =================================================================================== -->
<!-- |    This document was autogenerated by xacro from robot.xacro                    | -->
<!-- |    EDITING THIS FILE BY HAND IS NOT RECOMMENDED                                 | -->
<!-- =================================================================================== -->
<robot name="robot">
  <material name="silver">
    <color rgba="0.700 0.700 0.700 1.000"/>
  </material>
  <transmission name="link_1_joint_tran">
    <type>transmission_interface/SimpleTransmission</type>
    <joint name="link_1_joint">
      <hardwareInterface>hardware_interface/VelocityJointInterface</hardwareInterface>
    </joint>
    <actuator name="link_1_joint_actr">
      <hardwareInterface>hardware_interface/VelocityJointInterface</hardwareInterface>
      <mechanicalReduction>1</mechanicalReduction>
    </actuator>
  </transmission>
  <transmission name="link_2_joint_tran">
    <type>transmission_interface/SimpleTransmission</type>
    <joint name="link_2_joint">
      <hardwareInterface>hardware_interface/VelocityJointInterface</hardwareInterface>
    </joint>
    <actuator name="link_2_joint_actr">
      <hardwareInterface>hardware_interface/VelocityJointInterface</hardwareInterface>
      <mechanicalReduction>1</mechanicalReduction>
    </actuator>
  </transmission>
  <transmission name="link_3_joint_tran">
    <type>transmission_interface/SimpleTransmission</type>
    <joint name="link_3_joint">
      <hardwareInterface>hardware_interface/VelocityJointInterface</hardwareInterface>
    </joint>
    <actuator name="link_3_joint_actr">
      <hardwareInterface>hardware_interface/VelocityJointInterface</hardwareInterface>
      <mechanicalReduction>1</mechanicalReduction>
    </actuator>
  </transmission>
  <transmission name="link_end_joint_tran">
    <type>transmission_interface/SimpleTransmission</type>
    <joint name="link_end_joint">
      <hardwareInterface>hardware_interface/VelocityJointInterface</hardwareInterface>
    </joint>
    <actuator name="link_end_joint_actr">
      <hardwareInterface>hardware_interface/VelocityJointInterface</hardwareInterface>
      <mechanicalReduction>1</mechanicalReduction>
    </actuator>
  </transmission>
  <transmission name="finger_1_joint_tran">
    <type>transmission_interface/SimpleTransmission</type>
    <joint name="finger_1_joint">
      <hardwareInterface>hardware_interface/VelocityJointInterface</hardwareInterface>
    </joint>
    <actuator name="finger_1_joint_actr">
      <hardwareInterface>hardware_interface/VelocityJointInterface</hardwareInterface>
      <mechanicalReduction>1</mechanicalReduction>
    </actuator>
  </transmission>
  <transmission name="finger_2_joint_tran">
    <type>transmission_interface/SimpleTransmission</type>
    <joint name="finger_2_joint">
      <hardwareInterface>hardware_interface/VelocityJointInterface</hardwareInterface>
    </joint>
    <actuator name="finger_2_joint_actr">
      <hardwareInterface>hardware_interface/VelocityJointInterface</hardwareInterface>
      <mechanicalReduction>1</mechanicalReduction>
    </actuator>
  </transmission>
  <transmission name="finger_3_joint_tran">
    <type>transmission_interface/SimpleTransmission</type>
    <joint name="finger_3_joint">
      <hardwareInterface>hardware_interface/VelocityJointInterface</hardwareInterface>
    </joint>
    <actuator name="finger_3_joint_actr">
      <hardwareInterface>hardware_interface/velocityJointInterface</hardwareInterface>
      <mechanicalReduction>1</mechanicalReduction>
    </actuator>
  </transmission>
  <transmission name="wheel_joint_front_left_tran">
    <type>transmission_interface/SimpleTransmission</type>
    <joint name="wheel_joint_front_left">
      <hardwareInterface>hardware_interface/VelocityJointInterface</hardwareInterface>
    </joint>
    <actuator name="wheel_joint_front_left_actr">
      <hardwareInterface>hardware_interface/VelocityJointInterface</hardwareInterface>
      <mechanicalReduction>1</mechanicalReduction>
    </actuator>
  </transmission>
  <transmission name="wheel_joint_back_right_tran">
    <type>transmission_interface/SimpleTransmission</type>
    <joint name="wheel_joint_back_right">
      <hardwareInterface>hardware_interface/VelocityJointInterface</hardwareInterface>
    </joint>
    <actuator name="wheel_joint_back_right_actr">
      <hardwareInterface>hardware_interface/VelocityJointInterface</hardwareInterface>
      <mechanicalReduction>1</mechanicalReduction>
    </actuator>
  </transmission>
  <transmission name="wheel_joint_front_right_tran">
    <type>transmission_interface/SimpleTransmission</type>
    <joint name="wheel_joint_front_right">
      <hardwareInterface>hardware_interface/VelocityJointInterface</hardwareInterface>
    </joint>
    <actuator name="wheel_joint_front_right_actr">
      <hardwareInterface>hardware_interface/VelocityJointInterface</hardwareInterface>
      <mechanicalReduction>1</mechanicalReduction>
    </actuator>
  </transmission>
  <transmission name="wheel_joint_back_left_tran">
    <type>transmission_interface/SimpleTransmission</type>
    <joint name="wheel_joint_back_left">
      <hardwareInterface>hardware_interface/VelocityJointInterface</hardwareInterface>
    </joint>
    <actuator name="wheel_joint_back_left_actr">
      <hardwareInterface>hardware_interface/VelocityJointInterface</hardwareInterface>
      <mechanicalReduction>1</mechanicalReduction>
    </actuator>
  </transmission>
  <transmission name="arm_base_joint_tran">
    <type>transmission_interface/SimpleTransmission</type>
    <joint name="arm_base_joint">
      <hardwareInterface>hardware_interface/VelocityJointInterface</hardwareInterface>
    </joint>
    <actuator name="arm_base_joint_actr">
      <hardwareInterface>hardware_interface/VelocityJointInterface</hardwareInterface>
      <mechanicalReduction>1</mechanicalReduction>
    </actuator>
  </transmission>
  <transmission name="camera_revolute_tran">
    <type>transmission_interface/SimpleTransmission</type>
    <joint name="camera_revolute">
      <hardwareInterface>hardware_interface/VelocityJointInterface</hardwareInterface>
    </joint>
    <actuator name="camera_revolute_actr">
      <hardwareInterface>hardware_interface/VelocityJointInterface</hardwareInterface>
      <mechanicalReduction>1</mechanicalReduction>
    </actuator>
  </transmission>
  <gazebo>
    <plugin filename="libgazebo_ros_control.so" name="gazebo_ros_control">
      <!-- <robotNamespace>robot</robotNamespace> -->
      <robotSimType>gazebo_ros_control/DefaultRobotHWSim</robotSimType>
    </plugin>
  </gazebo>
  <!--

<gazebo>
    <plugin name="object_controller" filename="libgazebo_ros_planar_move.so">
      <commandTopic>cmd_vel</commandTopic>
      <odometryTopic>odom</odometryTopic>
      <odometryFrame>odom</odometryFrame>
      <odometryRate>20.0</odometryRate>
      <robotBaseFrame>base_link</robotBaseFrame>
    </plugin>
</gazebo>

-->
  <gazebo reference="RealSense_Camera_1">
    <gravity>true</gravity>
    <sensor name="imu_sensor" type="imu">
      <always_on>true</always_on>
      <update_rate>100</update_rate>
      <visualize>true</visualize>
      <topic>__default_topic__</topic>
      <plugin filename="libgazebo_ros_imu_sensor.so" name="imu_plugin">
        <topicName>meinimu</topicName>
        <bodyName>imu_link</bodyName>
        <updateRateHZ>10.0</updateRateHZ>
        <gaussianNoise>0.0</gaussianNoise>
        <xyzOffset>0 0 0</xyzOffset>
        <rpyOffset>0 0 0</rpyOffset>
        <frameName>imu_link</frameName>
        <initialOrientationAsReference>false</initialOrientationAsReference>
      </plugin>
      <pose>0 0 0 0 0 0</pose>
    </sensor>
  </gazebo>
  <gazebo reference="base_link">
    <material>Gazebo/Silver</material>
    <mu1>0.2</mu1>
    <mu2>0.2</mu2>
    <selfCollide>true</selfCollide>
    <gravity>true</gravity>
  </gazebo>
  <gazebo reference="arm_base_1">
    <material>Gazebo/Silver</material>
    <mu1>0.2</mu1>
    <mu2>0.2</mu2>
    <selfCollide>true</selfCollide>
  </gazebo>
  <gazebo reference="stepper_joint_1">
    <material>Gazebo/Silver</material>
    <mu1>0.2</mu1>
    <mu2>0.2</mu2>
    <selfCollide>true</selfCollide>
  </gazebo>
  <gazebo reference="link_1_1">
    <material>Gazebo/Silver</material>
    <mu1>0.2</mu1>
    <mu2>0.2</mu2>
    <selfCollide>true</selfCollide>
  </gazebo>
  <gazebo reference="link_2_1">
    <material>Gazebo/Silver</material>
    <mu1>0.2</mu1>
    <mu2>0.2</mu2>
    <selfCollide>true</selfCollide>
  </gazebo>
  <gazebo reference="link_3_1">
    <material>Gazebo/Silver</material>
    <mu1>0.2</mu1>
    <mu2>0.2</mu2>
    <selfCollide>true</selfCollide>
  </gazebo>
  <gazebo reference="link_end_1">
    <material>Gazebo/Silver</material>
    <mu1>0.2</mu1>
    <mu2>0.2</mu2>
    <selfCollide>true</selfCollide>
  </gazebo>
  <gazebo reference="NEMA_24_1_1">
    <material>Gazebo/Silver</material>
    <mu1>0.2</mu1>
    <mu2>0.2</mu2>
    <selfCollide>true</selfCollide>
  </gazebo>
  <gazebo reference="NEMA_24_2_1">
    <material>Gazebo/Silver</material>
    <mu1>0.2</mu1>
    <mu2>0.2</mu2>
    <selfCollide>true</selfCollide>
  </gazebo>
  <gazebo reference="NEMA_24_3_1">
    <material>Gazebo/Silver</material>
    <mu1>0.2</mu1>
    <mu2>0.2</mu2>
    <selfCollide>true</selfCollide>
  </gazebo>
  <gazebo reference="NEMA_24_4_1">
    <material>Gazebo/Silver</material>
    <mu1>0.2</mu1>
    <mu2>0.2</mu2>
    <selfCollide>true</selfCollide>
  </gazebo>
  <gazebo reference="gripper_base_1">
    <material>Gazebo/Silver</material>
    <mu1>0.2</mu1>
    <mu2>0.2</mu2>
    <selfCollide>true</selfCollide>
  </gazebo>
  <gazebo reference="gripper_finger_1_1">
    <material>Gazebo/Silver</material>
    <mu1>0.2</mu1>
    <mu2>0.2</mu2>
    <selfCollide>true</selfCollide>
  </gazebo>
  <gazebo reference="gripper_finger_2_1">
    <material>Gazebo/Silver</material>
    <mu1>0.2</mu1>
    <mu2>0.2</mu2>
    <selfCollide>true</selfCollide>
  </gazebo>
  <gazebo reference="gripper_finger_3_1">
    <material>Gazebo/Silver</material>
    <mu1>0.2</mu1>
    <mu2>0.2</mu2>
    <selfCollide>true</selfCollide>
  </gazebo>
  <gazebo reference="wheel_front_left_1">
    <material>Gazebo/Silver</material>
    <mu1>0.2</mu1>
    <mu2>0.2</mu2>
    <selfCollide>true</selfCollide>
  </gazebo>
  <gazebo reference="wheel_back_right_1">
    <material>Gazebo/Silver</material>
    <mu1>0.2</mu1>
    <mu2>0.2</mu2>
    <selfCollide>true</selfCollide>
  </gazebo>
  <gazebo reference="wheel_front_right_1">
    <material>Gazebo/Silver</material>
    <mu1>0.2</mu1>
    <mu2>0.2</mu2>
    <selfCollide>true</selfCollide>
  </gazebo>
  <gazebo reference="wheel_back_left_1">
    <material>Gazebo/Silver</material>
    <mu1>0.2</mu1>
    <mu2>0.2</mu2>
    <selfCollide>true</selfCollide>
  </gazebo>
  <gazebo reference="nylon_platform_1">
    <material>Gazebo/Silver</material>
    <mu1>0.2</mu1>
    <mu2>0.2</mu2>
    <selfCollide>true</selfCollide>
  </gazebo>
  <gazebo reference="base_turnable_1">
    <material>Gazebo/Silver</material>
    <mu1>0.2</mu1>
    <mu2>0.2</mu2>
    <selfCollide>true</selfCollide>
  </gazebo>
  <gazebo reference="NEMA_34_1">
    <material>Gazebo/Silver</material>
    <mu1>0.2</mu1>
    <mu2>0.2</mu2>
    <selfCollide>true</selfCollide>
  </gazebo>
  <gazebo reference="RealSense_Camera_1">
    <material>Gazebo/Silver</material>
    <mu1>0.2</mu1>
    <mu2>0.2</mu2>
    <selfCollide>true</selfCollide>
  </gazebo>
  <link name="world"/>
  <link name="base_link">
    <inertial>
      <origin rpy="0 0 0" xyz="-1.4771468453599796e-05 -0.4394102251855798 -0.5105474620020639"/>
      <mass value="90.2870635836035"/>
      <inertia ixx="16.958749" ixy="-1.4e-05" ixz="-0.000256" iyy="10.456164" iyz="-0.360506" izz="18.430844"/>
    </inertial>
    <visual>
      <origin rpy="0 0 0" xyz="0 0 0"/>
      <geometry>
        <mesh filename="package://robot_description/meshes/base_link.stl" scale="0.001 0.001 0.001"/>
      </geometry>
      <material name="silver"/>
    </visual>
    <collision>
      <origin rpy="0 0 0" xyz="0 0 0"/>
      <geometry>
        <mesh filename="package://robot_description/meshes/base_link.stl" scale="0.001 0.001 0.001"/>
      </geometry>
    </collision>
  </link>
  <link name="arm_base_1">
    <inertial>
      <origin rpy="0 0 0" xyz="-9.028631835610602e-14 -0.10852318160677443 0.07021749351752887"/>
      <mass value="2.9829690964186772"/>
      <inertia ixx="0.024074" ixy="-0.0" ixz="-0.0" iyy="0.017973" iyz="-0.002884" izz="0.02919"/>
    </inertial>
    <visual>
      <origin rpy="0 0 0" xyz="0.0 -0.075 0.18"/>
      <geometry>
        <mesh filename="package://robot_description/meshes/arm_base_1.stl" scale="0.001 0.001 0.001"/>
      </geometry>
      <material name="silver"/>
    </visual>
    <collision>
      <origin rpy="0 0 0" xyz="0.0 -0.075 0.18"/>
      <geometry>
        <mesh filename="package://robot_description/meshes/arm_base_1.stl" scale="0.001 0.001 0.001"/>
      </geometry>
    </collision>
  </link>
  <link name="stepper_joint_1">
    <inertial>
      <origin rpy="0 0 0" xyz="0.007499999999999989 1.3028467193976212e-13 1.3877787807814457e-16"/>
      <mass value="0.03498948817935604"/>
      <inertia ixx="7e-06" ixy="0.0" ixz="0.0" iyy="4e-06" iyz="0.0" izz="4e-06"/>
    </inertial>
    <visual>
      <origin rpy="0 0 0" xyz="-0.00348 -0.09 -0.085"/>
      <geometry>
        <mesh filename="package://robot_description/meshes/stepper_joint_1.stl" scale="0.001 0.001 0.001"/>
      </geometry>
      <material name="silver"/>
    </visual>
    <collision>
      <origin rpy="0 0 0" xyz="-0.00348 -0.09 -0.085"/>
      <geometry>
        <mesh filename="package://robot_description/meshes/stepper_joint_1.stl" scale="0.001 0.001 0.001"/>
      </geometry>
    </collision>
  </link>
  <link name="link_1_1">
    <inertial>
      <origin rpy="0 0 0" xyz="-0.00750000000000001 0.2614820661654451 1.3877787807814457e-16"/>
      <mass value="1.2422891158221263"/>
      <inertia ixx="0.03033" ixy="0.0" ixz="0.0" iyy="0.000414" iyz="-0.0" izz="0.029962"/>
    </inertial>
    <visual>
      <origin rpy="0 0 0" xyz="-0.00348 -0.09 -0.085"/>
      <geometry>
        <mesh filename="package://robot_description/meshes/link_1_1.stl" scale="0.001 0.001 0.001"/>
      </geometry>
      <material name="silver"/>
    </visual>
    <collision>
      <origin rpy="0 0 0" xyz="-0.00348 -0.09 -0.085"/>
      <geometry>
        <mesh filename="package://robot_description/meshes/link_1_1.stl" scale="0.001 0.001 0.001"/>
      </geometry>
    </collision>
  </link>
  <link name="link_2_1">
    <inertial>
      <origin rpy="0 0 0" xyz="0.026213672668365277 0.017799785433927795 1.3877787807814457e-16"/>
      <mass value="0.8743627585315773"/>
      <inertia ixx="0.000992" ixy="-8.4e-05" ixz="0.0" iyy="0.000864" iyz="0.0" izz="0.001253"/>
    </inertial>
    <visual>
      <origin rpy="0 0 0" xyz="-0.00348 -0.605 -0.085"/>
      <geometry>
        <mesh filename="package://robot_description/meshes/link_2_1.stl" scale="0.001 0.001 0.001"/>
      </geometry>
      <material name="silver"/>
    </visual>
    <collision>
      <origin rpy="0 0 0" xyz="-0.00348 -0.605 -0.085"/>
      <geometry>
        <mesh filename="package://robot_description/meshes/link_2_1.stl" scale="0.001 0.001 0.001"/>
      </geometry>
    </collision>
  </link>
  <link name="link_3_1">
    <inertial>
      <origin rpy="0 0 0" xyz="0.02499852381758487 0.1769222136151417 3.885780586188048e-16"/>
      <mass value="1.5478777520934175"/>
      <inertia ixx="0.032303" ixy="-0.002603" ixz="0.0" iyy="0.001209" iyz="0.0" izz="0.032482"/>
    </inertial>
    <visual>
      <origin rpy="0 0 0" xyz="-0.03848 -0.675 -0.085"/>
      <geometry>
        <mesh filename="package://robot_description/meshes/link_3_1.stl" scale="0.001 0.001 0.001"/>
      </geometry>
      <material name="silver"/>
    </visual>
    <collision>
      <origin rpy="0 0 0" xyz="-0.03848 -0.675 -0.085"/>
      <geometry>
        <mesh filename="package://robot_description/meshes/link_3_1.stl" scale="0.001 0.001 0.001"/>
      </geometry>
    </collision>
  </link>
  <link name="link_end_1">
    <inertial>
      <origin rpy="0 0 0" xyz="-0.03379678599677132 0.011579118062804872 4.163336342344337e-16"/>
      <mass value="1.063293416063342"/>
      <inertia ixx="0.000747" ixy="7.6e-05" ixz="0.0" iyy="0.00115" iyz="-0.0" izz="0.001353"/>
    </inertial>
    <visual>
      <origin rpy="0 0 0" xyz="-0.06848 -1.13 -0.085"/>
      <geometry>
        <mesh filename="package://robot_description/meshes/link_end_1.stl" scale="0.001 0.001 0.001"/>
      </geometry>
      <material name="silver"/>
    </visual>
    <collision>
      <origin rpy="0 0 0" xyz="-0.06848 -1.13 -0.085"/>
      <geometry>
        <mesh filename="package://robot_description/meshes/link_end_1.stl" scale="0.001 0.001 0.001"/>
      </geometry>
    </collision>
  </link>
  <link name="NEMA_24_1_1">
    <inertial>
      <origin rpy="0 0 0" xyz="-2.5568133205304072e-06 7.655954109564433e-08 0.047950794854052264"/>
      <mass value="2.4982959259379585"/>
      <inertia ixx="0.002718" ixy="-0.0" ixz="0.0" iyy="0.002718" iyz="-0.0" izz="0.001293"/>
    </inertial>
    <visual>
      <origin rpy="0 0 0" xyz="-0.0 0.125 0.12"/>
      <geometry>
        <mesh filename="package://robot_description/meshes/NEMA_24_1_1.stl" scale="0.001 0.001 0.001"/>
      </geometry>
      <material name="silver"/>
    </visual>
    <collision>
      <origin rpy="0 0 0" xyz="-0.0 0.125 0.12"/>
      <geometry>
        <mesh filename="package://robot_description/meshes/NEMA_24_1_1.stl" scale="0.001 0.001 0.001"/>
      </geometry>
    </collision>
  </link>
  <link name="NEMA_24_2_1">
    <inertial>
      <origin rpy="0 0 0" xyz="0.04795079485405226 7.655954106788876e-08 2.556813320619966e-06"/>
      <mass value="2.4982959259379585"/>
      <inertia ixx="0.001293" ixy="-0.0" ixz="-0.0" iyy="0.002718" iyz="0.0" izz="0.002718"/>
    </inertial>
    <visual>
      <origin rpy="0 0 0" xyz="-0.00348 -0.2275 -0.085"/>
      <geometry>
        <mesh filename="package://robot_description/meshes/NEMA_24_2_1.stl" scale="0.001 0.001 0.001"/>
      </geometry>
      <material name="silver"/>
    </visual>
    <collision>
      <origin rpy="0 0 0" xyz="-0.00348 -0.2275 -0.085"/>
      <geometry>
        <mesh filename="package://robot_description/meshes/NEMA_24_2_1.stl" scale="0.001 0.001 0.001"/>
      </geometry>
    </collision>
  </link>
  <link name="NEMA_24_3_1">
    <inertial>
      <origin rpy="0 0 0" xyz="7.65595409013553e-08 -0.04795079485405229 2.5568133205922106e-06"/>
      <mass value="2.4982959259379585"/>
      <inertia ixx="0.002718" ixy="0.0" ixz="0.0" iyy="0.001293" iyz="0.0" izz="0.002718"/>
    </inertial>
    <visual>
      <origin rpy="0 0 0" xyz="-0.03848 -0.575 -0.085"/>
      <geometry>
        <mesh filename="package://robot_description/meshes/NEMA_24_3_1.stl" scale="0.001 0.001 0.001"/>
      </geometry>
      <material name="silver"/>
    </visual>
    <collision>
      <origin rpy="0 0 0" xyz="-0.03848 -0.575 -0.085"/>
      <geometry>
        <mesh filename="package://robot_description/meshes/NEMA_24_3_1.stl" scale="0.001 0.001 0.001"/>
      </geometry>
    </collision>
  </link>
  <link name="NEMA_24_4_1">
    <inertial>
      <origin rpy="0 0 0" xyz="-7.655954063073844e-08 0.0009492051459477624 -0.029802556813320228"/>
      <mass value="2.4982959259379585"/>
      <inertia ixx="0.002718" ixy="-0.0" ixz="0.0" iyy="0.001293" iyz="-0.0" izz="0.002718"/>
    </inertial>
    <visual>
      <origin rpy="0 0 0" xyz="-0.03598 -0.625 -0.055"/>
      <geometry>
        <mesh filename="package://robot_description/meshes/NEMA_24_4_1.stl" scale="0.001 0.001 0.001"/>
      </geometry>
      <material name="silver"/>
    </visual>
    <collision>
      <origin rpy="0 0 0" xyz="-0.03598 -0.625 -0.055"/>
      <geometry>
        <mesh filename="package://robot_description/meshes/NEMA_24_4_1.stl" scale="0.001 0.001 0.001"/>
      </geometry>
    </collision>
  </link>
  <link name="gripper_base_1">
    <inertial>
      <origin rpy="0 0 0" xyz="-8.738046848588699e-10 0.03673655788581898 1.1906876873357675e-10"/>
      <mass value="1.1315792783817065"/>
      <inertia ixx="0.001126" ixy="0.0" ixz="-0.0" iyy="0.001318" iyz="-0.0" izz="0.001126"/>
    </inertial>
    <visual>
      <origin rpy="0 0 0" xyz="-0.02848 -1.18 -0.085"/>
      <geometry>
        <mesh filename="package://robot_description/meshes/gripper_base_1.stl" scale="0.001 0.001 0.001"/>
      </geometry>
      <material name="silver"/>
    </visual>
    <collision>
      <origin rpy="0 0 0" xyz="-0.02848 -1.18 -0.085"/>
      <geometry>
        <mesh filename="package://robot_description/meshes/gripper_base_1.stl" scale="0.001 0.001 0.001"/>
      </geometry>
    </collision>
  </link>
  <link name="gripper_finger_1_1">
    <inertial>
      <origin rpy="0 0 0" xyz="-3.2830821047880043e-10 0.022979968590664424 0.004865333770814467"/>
      <mass value="0.07511526055866109"/>
      <inertia ixx="1.7e-05" ixy="0.0" ixz="-0.0" iyy="3e-06" iyz="-0.0" izz="1.8e-05"/>
    </inertial>
    <visual>
      <origin rpy="0 0 0" xyz="-0.02848 -1.2645 -0.1175"/>
      <geometry>
        <mesh filename="package://robot_description/meshes/gripper_finger_1_1.stl" scale="0.001 0.001 0.001"/>
      </geometry>
      <material name="silver"/>
    </visual>
    <collision>
      <origin rpy="0 0 0" xyz="-0.02848 -1.2645 -0.1175"/>
      <geometry>
        <mesh filename="package://robot_description/meshes/gripper_finger_1_1.stl" scale="0.001 0.001 0.001"/>
      </geometry>
    </collision>
  </link>
  <link name="gripper_finger_2_1">
    <inertial>
      <origin rpy="0 0 0" xyz="0.004213328299858772 0.022979968590664646 -0.002432666827471383"/>
      <mass value="0.07511526055866109"/>
      <inertia ixx="1.8e-05" ixy="-0.0" ixz="-0.0" iyy="3e-06" iyz="0.0" izz="1.8e-05"/>
    </inertial>
    <visual>
      <origin rpy="0 0 0" xyz="-0.056626 -1.2645 -0.06875"/>
      <geometry>
        <mesh filename="package://robot_description/meshes/gripper_finger_2_1.stl" scale="0.001 0.001 0.001"/>
      </geometry>
      <material name="silver"/>
    </visual>
    <collision>
      <origin rpy="0 0 0" xyz="-0.056626 -1.2645 -0.06875"/>
      <geometry>
        <mesh filename="package://robot_description/meshes/gripper_finger_2_1.stl" scale="0.001 0.001 0.001"/>
      </geometry>
    </collision>
  </link>
  <link name="gripper_finger_3_1">
    <inertial>
      <origin rpy="0 0 0" xyz="-0.004213328102255366 0.022979968590664646 -0.002432667169729938"/>
      <mass value="0.07511526055866109"/>
      <inertia ixx="1.8e-05" ixy="0.0" ixz="0.0" iyy="3e-06" iyz="0.0" izz="1.8e-05"/>
    </inertial>
    <visual>
      <origin rpy="0 0 0" xyz="-0.000334 -1.2645 -0.06875"/>
      <geometry>
        <mesh filename="package://robot_description/meshes/gripper_finger_3_1.stl" scale="0.001 0.001 0.001"/>
      </geometry>
      <material name="silver"/>
    </visual>
    <collision>
      <origin rpy="0 0 0" xyz="-0.000334 -1.2645 -0.06875"/>
      <geometry>
        <mesh filename="package://robot_description/meshes/gripper_finger_3_1.stl" scale="0.001 0.001 0.001"/>
      </geometry>
    </collision>
  </link>
  <link name="wheel_front_left_1">
    <inertial>
      <origin rpy="0 0 0" xyz="0.02746332660479106 2.091868814349529e-07 -1.3465862747086277e-07"/>
      <mass value="3.2600262308265497"/>
      <inertia ixx="0.009383" ixy="-0.0" ixz="0.0" iyy="0.005841" iyz="0.0" izz="0.005841"/>
    </inertial>
    <visual>
      <origin rpy="0 0 0" xyz="0.390822 0.049471 0.702118"/>
      <geometry>
        <mesh filename="package://robot_description/meshes/wheel_front_left_1.stl" scale="0.001 0.001 0.001"/>
      </geometry>
      <material name="silver"/>
    </visual>
    <collision>
      <origin rpy="0 0 0" xyz="0.390822 0.049471 0.702118"/>
      <geometry>
        <mesh filename="package://robot_description/meshes/wheel_front_left_1.stl" scale="0.001 0.001 0.001"/>
      </geometry>
    </collision>
  </link>
  <link name="wheel_back_right_1">
    <inertial>
      <origin rpy="0 0 0" xyz="-0.027463123209301332 -3.592060286994325e-07 -1.3465862713779586e-07"/>
      <mass value="3.2600262308265497"/>
      <inertia ixx="0.009383" ixy="-0.0" ixz="-0.0" iyy="0.005841" iyz="-0.0" izz="0.005841"/>
    </inertial>
    <visual>
      <origin rpy="0 0 0" xyz="-0.390178 0.839249 0.702118"/>
      <geometry>
        <mesh filename="package://robot_description/meshes/wheel_back_right_1.stl" scale="0.001 0.001 0.001"/>
      </geometry>
      <material name="silver"/>
    </visual>
    <collision>
      <origin rpy="0 0 0" xyz="-0.390178 0.839249 0.702118"/>
      <geometry>
        <mesh filename="package://robot_description/meshes/wheel_back_right_1.stl" scale="0.001 0.001 0.001"/>
      </geometry>
    </collision>
  </link>
  <link name="wheel_front_right_1">
    <inertial>
      <origin rpy="0 0 0" xyz="-0.027463106395432424 -3.5966591916541946e-07 -1.353796763581272e-07"/>
      <mass value="3.260021800926923"/>
      <inertia ixx="0.009383" ixy="0.0" ixz="-0.0" iyy="0.005841" iyz="-0.0" izz="0.005841"/>
    </inertial>
    <visual>
      <origin rpy="0 0 0" xyz="-0.390178 0.049249 0.702118"/>
      <geometry>
        <mesh filename="package://robot_description/meshes/wheel_front_right_1.stl" scale="0.001 0.001 0.001"/>
      </geometry>
      <material name="silver"/>
    </visual>
    <collision>
      <origin rpy="0 0 0" xyz="-0.390178 0.049249 0.702118"/>
      <geometry>
        <mesh filename="package://robot_description/meshes/wheel_front_right_1.stl" scale="0.001 0.001 0.001"/>
      </geometry>
    </collision>
  </link>
  <link name="wheel_back_left_1">
    <inertial>
      <origin rpy="0 0 0" xyz="0.027463309790926482 2.096467722756401e-07 -1.353796763581272e-07"/>
      <mass value="3.260021800926923"/>
      <inertia ixx="0.009383" ixy="0.0" ixz="0.0" iyy="0.005841" iyz="0.0" izz="0.005841"/>
    </inertial>
    <visual>
      <origin rpy="0 0 0" xyz="0.390822 0.839471 0.702118"/>
      <geometry>
        <mesh filename="package://robot_description/meshes/wheel_back_left_1.stl" scale="0.001 0.001 0.001"/>
      </geometry>
      <material name="silver"/>
    </visual>
    <collision>
      <origin rpy="0 0 0" xyz="0.390822 0.839471 0.702118"/>
      <geometry>
        <mesh filename="package://robot_description/meshes/wheel_back_left_1.stl" scale="0.001 0.001 0.001"/>
      </geometry>
    </collision>
  </link>
  <link name="nylon_platform_1">
    <inertial>
      <origin rpy="0 0 0" xyz="-3.1974423109204507e-16 -8.352245506326739e-08 0.0031754317485722106"/>
      <mass value="15.086134521600004"/>
      <inertia ixx="0.31737" ixy="0.0" ixz="0.0" iyy="0.456263" iyz="-0.0" izz="0.773531"/>
    </inertial>
    <visual>
      <origin rpy="0 0 0" xyz="0.0 0.682138 0.491798"/>
      <geometry>
        <mesh filename="package://robot_description/meshes/nylon_platform_1.stl" scale="0.001 0.001 0.001"/>
      </geometry>
      <material name="silver"/>
    </visual>
    <collision>
      <origin rpy="0 0 0" xyz="0.0 0.682138 0.491798"/>
      <geometry>
        <mesh filename="package://robot_description/meshes/nylon_platform_1.stl" scale="0.001 0.001 0.001"/>
      </geometry>
    </collision>
  </link>
  <link name="base_turnable_1">
    <inertial>
      <origin rpy="0 0 0" xyz="-0.019680888861266014 0.005428549860960602 0.02350645084014471"/>
      <mass value="6.27904528107532"/>
      <inertia ixx="0.109757" ixy="-0.000233" ixz="0.021421" iyy="0.115631" iyz="-0.002428" izz="0.018856"/>
    </inertial>
    <visual>
      <origin rpy="0 0 0" xyz="-0.0 -0.0 -0.0"/>
      <geometry>
        <mesh filename="package://robot_description/meshes/base_turnable_1.stl" scale="0.001 0.001 0.001"/>
      </geometry>
      <material name="silver"/>
    </visual>
    <collision>
      <origin rpy="0 0 0" xyz="-0.0 -0.0 -0.0"/>
      <geometry>
        <mesh filename="package://robot_description/meshes/base_turnable_1.stl" scale="0.001 0.001 0.001"/>
      </geometry>
    </collision>
  </link>
  <link name="NEMA_34_1">
    <inertial>
      <origin rpy="0 0 0" xyz="0.07651505285685478 -3.2210028768075993e-06 -5.551115123125783e-17"/>
      <mass value="5.3165200877598835"/>
      <inertia ixx="0.005731" ixy="-2e-06" ixz="0.0" iyy="0.014133" iyz="-0.0" izz="0.014133"/>
    </inertial>
    <visual>
      <origin rpy="0 0 0" xyz="-0.04 -0.09 -0.085"/>
      <geometry>
        <mesh filename="package://robot_description/meshes/NEMA_34_1.stl" scale="0.001 0.001 0.001"/>
      </geometry>
      <material name="silver"/>
    </visual>
    <collision>
      <origin rpy="0 0 0" xyz="-0.04 -0.09 -0.085"/>
      <geometry>
        <mesh filename="package://robot_description/meshes/NEMA_34_1.stl" scale="0.001 0.001 0.001"/>
      </geometry>
    </collision>
  </link>
  <link name="RealSense_Camera_1"/>
  <!--
<link name="RealSense_Camera_1">
  <inertial>
    <origin rpy="0 0 0" xyz="-0.0010696020063957895 0.0010440004277679424 0.012011380076091704"/>
    <mass value="0.2739287989936542"/>
    <inertia ixx="2.6e-05" ixy="-2e-06" ixz="0.0" iyy="0.000177" iyz="0.0" izz="0.000178"/>
  </inertial>
  <visual>
    <origin rpy="0 0 0" xyz="0.09 -0.005 -0.629827"/>
    <geometry>
      <mesh filename="package://robot_description/meshes/RealSense_Camera_1.stl" scale="0.001 0.001 0.001"/>
    </geometry>
    <material name="silver"/>
  </visual>
  <collision>
    <origin rpy="0 0 0" xyz="0.09 -0.005 -0.629827"/>
    <geometry>
      <mesh filename="package://robot_description/meshes/RealSense_Camera_1.stl" scale="0.001 0.001 0.001"/>
    </geometry>
  </collision>
</link>
-->
  <material name="camera_aluminum">
    <color rgba="0.5 0.5 0.5 1"/>
  </material>
  <!-- camera body, with origin at bottom screw mount -->
  <joint name="camera_joint" type="fixed">
    <origin rpy="0 0 0" xyz="0 0 0"/>
    <parent link="RealSense_Camera_1"/>
    <child link="camera_bottom_screw_frame"/>
  </joint>
  <link name="camera_bottom_screw_frame"/>
  <joint name="camera_link_joint" type="fixed">
    <origin rpy="0 0 0" xyz="0 0.0175 0.0125"/>
    <parent link="camera_bottom_screw_frame"/>
    <child link="camera_link"/>
  </joint>
  <link name="camera_link">
    <visual>
      <origin rpy="1.5707963267948966 0 1.5707963267948966" xyz="0.0149 -0.0175 0"/>
      <geometry>
        <!-- <box size="${d435_cam_width} ${d435_cam_height} ${d435_cam_depth}"/> -->
        <mesh filename="package://robot_description/meshes/d435.dae"/>
        <!--<mesh filename="package://realsense2_description/meshes/d435/d435.dae" />-->
      </geometry>
      <material name="camera_aluminum"/>
    </visual>
    <collision>
      <origin rpy="0 0 0" xyz="0 -0.0175 0"/>
      <geometry>
        <box size="0.02505 0.09 0.025"/>
      </geometry>
    </collision>
    <inertial>
      <!-- The following are not reliable values, and should not be used for modeling -->
      <mass value="0.564"/>
      <origin xyz="0 0 0"/>
      <inertia ixx="0.003881243" ixy="0.0" ixz="0.0" iyy="0.000498940" iyz="0.0" izz="0.003879257"/>
    </inertial>
  </link>
  <!-- camera depth joints and links -->
  <joint name="camera_depth_joint" type="fixed">
    <origin rpy="0 0 0" xyz="0 0 0"/>
    <parent link="camera_link"/>
    <child link="camera_depth_frame"/>
  </joint>
  <link name="camera_depth_frame"/>
  <joint name="camera_depth_optical_joint" type="fixed">
    <origin rpy="-1.5707963267948966 0 -1.5707963267948966" xyz="0 0 0"/>
    <parent link="camera_depth_frame"/>
    <child link="camera_depth_optical_frame"/>
  </joint>
  <link name="camera_depth_optical_frame"/>
  <!-- camera left IR joints and links -->
  <joint name="camera_left_ir_joint" type="fixed">
    <origin rpy="0 0 0" xyz="0 0.0 0"/>
    <parent link="camera_depth_frame"/>
    <child link="camera_left_ir_frame"/>
  </joint>
  <link name="camera_left_ir_frame"/>
  <joint name="camera_left_ir_optical_joint" type="fixed">
    <origin rpy="-1.5707963267948966 0 -1.5707963267948966" xyz="0 0 0"/>
    <parent link="camera_left_ir_frame"/>
    <child link="camera_left_ir_optical_frame"/>
  </joint>
  <link name="camera_left_ir_optical_frame"/>
  <!-- camera right IR joints and links -->
  <joint name="camera_right_ir_joint" type="fixed">
    <origin rpy="0 0 0" xyz="0 -0.05 0"/>
    <parent link="camera_depth_frame"/>
    <child link="camera_right_ir_frame"/>
  </joint>
  <link name="camera_right_ir_frame"/>
  <joint name="camera_right_ir_optical_joint" type="fixed">
    <origin rpy="-1.5707963267948966 0 -1.5707963267948966" xyz="0 0 0"/>
    <parent link="camera_right_ir_frame"/>
    <child link="camera_right_ir_optical_frame"/>
  </joint>
  <link name="camera_right_ir_optical_frame"/>
  <!-- camera color joints and links -->
  <joint name="camera_color_joint" type="fixed">
    <origin rpy="0 0 0" xyz="0 0.015 0"/>
    <parent link="camera_depth_frame"/>
    <child link="camera_color_frame"/>
  </joint>
  <link name="camera_color_frame"/>
  <joint name="camera_color_optical_joint" type="fixed">
    <origin rpy="-1.5707963267948966 0 -1.5707963267948966" xyz="0 0 0"/>
    <parent link="camera_color_frame"/>
    <child link="camera_color_optical_frame"/>
  </joint>
  <link name="camera_color_optical_frame"/>
  <gazebo reference="camera_link">
    <self_collide>0</self_collide>
    <enable_wind>0</enable_wind>
    <kinematic>0</kinematic>
    <gravity>1</gravity>
    <!--<mu>1</mu>-->
    <mu2>1</mu2>
    <fdir1>0 0 0</fdir1>
    <!--<slip1>0</slip1>
      <slip2>0</slip2>-->
    <kp>1e+13</kp>
    <kd>1</kd>
    <!--<max_vel>0.01</max_vel>
      <min_depth>0</min_depth>-->
    <sensor name="cameracolor" type="camera">
      <camera name="camera">
        <horizontal_fov>1.2112585008840648</horizontal_fov>
        <image>
          <width>1920</width>
          <height>1080</height>
          <format>RGB_INT8</format>
        </image>
        <clip>
          <near>0.1</near>
          <far>100</far>
        </clip>
        <noise>
          <type>gaussian</type>
          <mean>0.0</mean>
          <stddev>0.007</stddev>
        </noise>
      </camera>
      <always_on>1</always_on>
      <update_rate>15</update_rate>
      <visualize>1</visualize>
    </sensor>
    <sensor name="cameraired1" type="camera">
      <camera name="camera">
        <horizontal_fov>1.4870205226991688</horizontal_fov>
        <image>
          <width>1280</width>
          <height>720</height>
          <format>L_INT8</format>
        </image>
        <clip>
          <near>0.1</near>
          <far>100</far>
        </clip>
        <noise>
          <type>gaussian</type>
          <mean>0.0</mean>
          <stddev>0.05</stddev>
        </noise>
      </camera>
      <always_on>0</always_on>
      <update_rate>10</update_rate>
      <visualize>0</visualize>
    </sensor>
    <sensor name="cameraired2" type="camera">
      <camera name="camera">
        <horizontal_fov>1.4870205226991688</horizontal_fov>
        <image>
          <width>1280</width>
          <height>720</height>
          <format>L_INT8</format>
        </image>
        <clip>
          <near>0.1</near>
          <far>100</far>
        </clip>
        <noise>
          <type>gaussian</type>
          <mean>0.0</mean>
          <stddev>0.05</stddev>
        </noise>
      </camera>
      <always_on>0</always_on>
      <update_rate>10</update_rate>
      <visualize>0</visualize>
    </sensor>
    <sensor name="cameradepth" type="depth">
      <camera name="camera">
        <horizontal_fov>1.4870205226991688</horizontal_fov>
        <image>
          <width>1280</width>
          <height>720</height>
        </image>
        <clip>
          <near>0.1</near>
          <far>100</far>
        </clip>
        <noise>
          <type>gaussian</type>
          <mean>0.0</mean>
          <stddev>0.100</stddev>
        </noise>
      </camera>
      <always_on>1</always_on>
      <update_rate>90</update_rate>
      <visualize>0</visualize>
    </sensor>
  </gazebo>
  <gazebo>
    <plugin filename="librealsense_gazebo_plugin.so" name="camera">
      <prefix>camera</prefix>
      <depthUpdateRate>30.0</depthUpdateRate>
      <colorUpdateRate>30.0</colorUpdateRate>
      <infraredUpdateRate>10.0</infraredUpdateRate>
      <depthTopicName>depth/image_raw</depthTopicName>
      <depthCameraInfoTopicName>depth/camera_info</depthCameraInfoTopicName>
      <colorTopicName>color/image_raw</colorTopicName>
      <colorCameraInfoTopicName>color/camera_info</colorCameraInfoTopicName>
      <infrared1TopicName>infra1/image_raw</infrared1TopicName>
      <infrared1CameraInfoTopicName>infra1/camera_info</infrared1CameraInfoTopicName>
      <infrared2TopicName>infra2/image_raw</infrared2TopicName>
      <infrared2CameraInfoTopicName>infra2/camera_info</infrared2CameraInfoTopicName>
      <colorOpticalframeName>camera_color_optical_frame</colorOpticalframeName>
      <depthOpticalframeName>camera_depth_optical_frame</depthOpticalframeName>
      <infrared1OpticalframeName>camera_left_ir_optical_frame</infrared1OpticalframeName>
      <infrared2OpticalframeName>camera_right_ir_optical_frame</infrared2OpticalframeName>
      <rangeMinDepth>0.2</rangeMinDepth>
      <rangeMaxDepth>3.0</rangeMaxDepth>
      <pointCloud>false</pointCloud>
      <pointCloudTopicName>depth/points</pointCloudTopicName>
      <pointCloudCutoff>0.5</pointCloudCutoff>
    </plugin>
  </gazebo>
  <joint name="base_to_world" type="fixed">
    <origin rpy="0 0 0" xyz="0.0 0.0 0.77217"/>
    <parent link="world"/>
    <child link="base_link"/>
  </joint>
  <joint name="Rigid1" type="fixed">
    <origin rpy="0 0 0" xyz="0.0 0.075 -0.18"/>
    <parent link="base_link"/>
    <child link="arm_base_1"/>
  </joint>
  <joint name="Rigid4" type="fixed">
    <origin rpy="0 0 0" xyz="-0.03652 0.0 0.0"/>
    <parent link="NEMA_34_1"/>
    <child link="stepper_joint_1"/>
  </joint>
  <joint name="link_1_joint" type="continuous">
    <origin rpy="0 0 0" xyz="0.0 0.0 0.0"/>
    <parent link="stepper_joint_1"/>
    <child link="link_1_1"/>
    <axis xyz="-1.0 0.0 -0.0"/>
  </joint>
  <joint name="link_2_joint" type="continuous">
    <origin rpy="0 0 0" xyz="0.0 0.515 0.0"/>
    <parent link="link_1_1"/>
    <child link="link_2_1"/>
    <axis xyz="-1.0 0.0 -0.0"/>
  </joint>
  <joint name="link_3_joint" type="continuous">
    <origin rpy="0 0 0" xyz="0.035 0.07 0.0"/>
    <parent link="link_2_1"/>
    <child link="link_3_1"/>
    <axis xyz="-0.0 -1.0 -0.0"/>
  </joint>
  <joint name="link_end_joint" type="continuous">
    <origin rpy="0 0 0" xyz="0.03 0.455 0.0"/>
    <parent link="link_3_1"/>
    <child link="link_end_1"/>
    <axis xyz="1.0 -0.0 0.0"/>
  </joint>
  <joint name="Rigid9" type="fixed">
    <origin rpy="0 0 0" xyz="0.0 -0.2 0.06"/>
    <parent link="arm_base_1"/>
    <child link="NEMA_24_1_1"/>
  </joint>
  <joint name="Rigid10" type="fixed">
    <origin rpy="0 0 0" xyz="0.0 0.1375 0.0"/>
    <parent link="link_1_1"/>
    <child link="NEMA_24_2_1"/>
  </joint>
  <joint name="Rigid11" type="fixed">
    <origin rpy="0 0 0" xyz="0.035 -0.03 0.0"/>
    <parent link="link_2_1"/>
    <child link="NEMA_24_3_1"/>
  </joint>
  <joint name="Rigid12" type="fixed">
    <origin rpy="0 0 0" xyz="0.0325 0.02 -0.03"/>
    <parent link="link_2_1"/>
    <child link="NEMA_24_4_1"/>
  </joint>
  <joint name="Rigid18" type="fixed">
    <origin rpy="0 0 0" xyz="-0.04 0.05 0.0"/>
    <parent link="link_end_1"/>
    <child link="gripper_base_1"/>
  </joint>
  <joint name="finger_1_joint" type="continuous">
    <origin rpy="0 0 0" xyz="0.0 0.0845 0.0325"/>
    <parent link="gripper_base_1"/>
    <child link="gripper_finger_1_1"/>
    <axis xyz="1.0 0.0 0.0"/>
  </joint>
  <joint name="finger_2_joint" type="continuous">
    <origin rpy="0 0 0" xyz="0.028146 0.0845 -0.01625"/>
    <parent link="gripper_base_1"/>
    <child link="gripper_finger_2_1"/>
    <axis xyz="-0.5 0.0 -0.866025"/>
  </joint>
  <joint name="finger_3_joint" type="continuous">
    <origin rpy="0 0 0" xyz="-0.028146 0.0845 -0.01625"/>
    <parent link="gripper_base_1"/>
    <child link="gripper_finger_3_1"/>
    <axis xyz="-0.5 -0.0 0.866025"/>
  </joint>
  <joint name="wheel_joint_front_left" type="continuous">
    <origin rpy="0 0 0" xyz="-0.390822 -0.049471 -0.702118"/>
    <parent link="base_link"/>
    <child link="wheel_front_left_1"/>
    <axis xyz="1.0 0.0 -0.0"/>
  </joint>
  <joint name="wheel_joint_back_right" type="continuous">
    <origin rpy="0 0 0" xyz="0.390178 -0.839249 -0.702118"/>
    <parent link="base_link"/>
    <child link="wheel_back_right_1"/>
    <axis xyz="-1.0 0.0 0.0"/>
  </joint>
  <joint name="wheel_joint_front_right" type="continuous">
    <origin rpy="0 0 0" xyz="0.390178 -0.049249 -0.702118"/>
    <parent link="base_link"/>
    <child link="wheel_front_right_1"/>
    <axis xyz="-1.0 0.0 0.0"/>
  </joint>
  <joint name="wheel_joint_back_left" type="continuous">
    <origin rpy="0 0 0" xyz="-0.390822 -0.839471 -0.702118"/>
    <parent link="base_link"/>
    <child link="wheel_back_left_1"/>
    <axis xyz="1.0 0.0 -0.0"/>
  </joint>
  <joint name="Rigid26" type="fixed">
    <origin rpy="0 0 0" xyz="0.0 -0.682138 -0.491798"/>
    <parent link="base_link"/>
    <child link="nylon_platform_1"/>
  </joint>
  <joint name="arm_base_joint" type="continuous">
    <origin rpy="0 0 0" xyz="0.0 -0.075 0.18"/>
    <parent link="arm_base_1"/>
    <child link="base_turnable_1"/>
    <axis xyz="-0.0 0.0 -1.0"/>
  </joint>
  <joint name="Rigid28" type="fixed">
    <origin rpy="0 0 0" xyz="0.04 0.09 0.085"/>
    <parent link="base_turnable_1"/>
    <child link="NEMA_34_1"/>
  </joint>
  <joint name="camera_revolute" type="continuous">
    <origin rpy="0 0 0" xyz="-0.09 0.005 0.629827"/>
    <parent link="base_turnable_1"/>
    <child link="RealSense_Camera_1"/>
    <axis xyz="0.0 0.0 -1.0"/>
  </joint>
</robot>

