<?xml version="1.0" ?>
<!-- =================================================================================== -->
<!-- |    This document was autogenerated by xacro from robot.xacro                    | -->
<!-- |    EDITING THIS FILE BY HAND IS NOT RECOMMENDED                                 | -->
<!-- =================================================================================== -->
<robot name="robot">
  <material name="silver">
    <color rgba="0.700 0.700 0.700 1.000"/>
  </material>
  <transmission name="link_1_joint_tran">
    <type>transmission_interface/SimpleTransmission</type>
    <joint name="link_1_joint">
      <hardwareInterface>hardware_interface/VelocityJointInterface</hardwareInterface>
    </joint>
    <actuator name="link_1_joint_actr">
      <hardwareInterface>hardware_interface/VelocityJointInterface</hardwareInterface>
      <mechanicalReduction>1</mechanicalReduction>
    </actuator>
  </transmission>
  <transmission name="link_2_joint_tran">
    <type>transmission_interface/SimpleTransmission</type>
    <joint name="link_2_joint">
      <hardwareInterface>hardware_interface/VelocityJointInterface</hardwareInterface>
    </joint>
    <actuator name="link_2_joint_actr">
      <hardwareInterface>hardware_interface/VelocityJointInterface</hardwareInterface>
      <mechanicalReduction>1</mechanicalReduction>
    </actuator>
  </transmission>
  <transmission name="link_3_joint_tran">
    <type>transmission_interface/SimpleTransmission</type>
    <joint name="link_3_joint">
      <hardwareInterface>hardware_interface/VelocityJointInterface</hardwareInterface>
    </joint>
    <actuator name="link_3_joint_actr">
      <hardwareInterface>hardware_interface/VelocityJointInterface</hardwareInterface>
      <mechanicalReduction>1</mechanicalReduction>
    </actuator>
  </transmission>
  <transmission name="link_end_joint_tran">
    <type>transmission_interface/SimpleTransmission</type>
    <joint name="link_end_joint">
      <hardwareInterface>hardware_interface/VelocityJointInterface</hardwareInterface>
    </joint>
    <actuator name="link_end_joint_actr">
      <hardwareInterface>hardware_interface/VelocityJointInterface</hardwareInterface>
      <mechanicalReduction>1</mechanicalReduction>
    </actuator>
  </transmission>
  <!--

<transmission name="finger_1_joint_tran">
  <type>transmission_interface/SimpleTransmission</type>
  <joint name="finger_1_joint">
    <hardwareInterface>hardware_interface/VelocityJointInterface</hardwareInterface>
  </joint>
  <actuator name="finger_1_joint_actr">
    <hardwareInterface>hardware_interface/VelocityJointInterface</hardwareInterface>
    <mechanicalReduction>1</mechanicalReduction>
  </actuator>
</transmission>

<transmission name="finger_2_joint_tran">
  <type>transmission_interface/SimpleTransmission</type>
  <joint name="finger_2_joint">
    <hardwareInterface>hardware_interface/VelocityJointInterface</hardwareInterface>
  </joint>
  <actuator name="finger_2_joint_actr">
    <hardwareInterface>hardware_interface/VelocityJointInterface</hardwareInterface>
    <mechanicalReduction>1</mechanicalReduction>
  </actuator>
</transmission>

<transmission name="finger_3_joint_tran">
  <type>transmission_interface/SimpleTransmission</type>
  <joint name="finger_3_joint">
    <hardwareInterface>hardware_interface/VelocityJointInterface</hardwareInterface>
  </joint>
  <actuator name="finger_3_joint_actr">
    <hardwareInterface>hardware_interface/VelocityJointInterface</hardwareInterface>
    <mechanicalReduction>1</mechanicalReduction>
  </actuator>
</transmission>
-->
  <!-- <transmission name="gripper_axis_rev_tran">
  <type>transmission_interface/SimpleTransmission</type>
  <joint name="gripper_axis_rev">
    <hardwareInterface>hardware_interface/VelocityJointInterface</hardwareInterface>
  </joint>
  <actuator name="gripper_axis_rev_actr">
    <hardwareInterface>hardware_interface/VelocityJointInterface</hardwareInterface>
    <mechanicalReduction>1</mechanicalReduction>
  </actuator>
</transmission> -->
  <!--


<joint name="Rev45" type="continuous">
  <origin rpy="0 0 0" xyz="0.0845 -0.0325 0.0"/>
  <parent link="modified_gripper_v3_1"/>
  <child link="finger_1_1"/>
  <axis xyz="0.0 0.0 -1.0"/>
</joint>

<joint name="Rev46" type="continuous">
  <origin rpy="0 0 0" xyz="0.049755 -0.89 -1.683756"/>
  <parent link="modified_gripper_v3_1"/>
  <child link="finger_1_3"/>
  <axis xyz="-0.0 0.0 1.0"/>
</joint>

<joint name="Rev47" type="continuous">
  <origin rpy="0 0 0" xyz="0.004109 0.09 0.629833"/>
  <parent link="base_turnable_1"/>
  <child link="camera_stuff_MODIFIED_camera_pitch_rotation_stand_v1_1"/>
  <axis xyz="0.001414 0.0 -0.999999"/>
</joint>


-->
  <!--Finger 1_1 -->
  <transmission name="finger_1_tran">
    <type>transmission_interface/SimpleTransmission</type>
    <joint name="finger_1_revolute_joint">
      <hardwareInterface>hardware_interface/VelocityJointInterface</hardwareInterface>
    </joint>
    <actuator name="finger_1_revolute_actr">
      <hardwareInterface>hardware_interface/VelocityJointInterface</hardwareInterface>
      <mechanicalReduction>1</mechanicalReduction>
    </actuator>
  </transmission>
  <!-- FINGER_1_2 -->
  <transmission name="finger_2_tran">
    <type>transmission_interface/SimpleTransmission</type>
    <joint name="finger_2_revolute_joint">
      <hardwareInterface>hardware_interface/VelocityJointInterface</hardwareInterface>
    </joint>
    <actuator name="finger_2_revolute_actr">
      <hardwareInterface>hardware_interface/VelocityJointInterface</hardwareInterface>
      <mechanicalReduction>1</mechanicalReduction>
    </actuator>
  </transmission>
  <!-- camera  pitch rotation stand yaw -->
  <transmission name="camera_yaw_rotation_tran">
    <type>transmission_interface/SimpleTransmission</type>
    <joint name="camera_yaw_rotation">
      <hardwareInterface>hardware_interface/VelocityJointInterface</hardwareInterface>
    </joint>
    <actuator name="camera_yaw_rotation_actr">
      <hardwareInterface>hardware_interface/VelocityJointInterface</hardwareInterface>
      <mechanicalReduction>1</mechanicalReduction>
    </actuator>
  </transmission>
  <!-- camera_stuff_MODIFIED_camera_pitch_rotation_base_v1_1 pitch -->
  <transmission name="camera_pitch_rotation_tran">
    <type>transmission_interface/SimpleTransmission</type>
    <joint name="camera_pitch_rotation">
      <hardwareInterface>hardware_interface/VelocityJointInterface</hardwareInterface>
    </joint>
    <actuator name="camera_pitch_rotation_actr">
      <hardwareInterface>hardware_interface/VelocityJointInterface</hardwareInterface>
      <mechanicalReduction>1</mechanicalReduction>
    </actuator>
  </transmission>
  <!--
<transmission name="Rev49_tran">
  <type>transmission_interface/SimpleTransmission</type>
  <joint name="Rev49">
    <hardwareInterface>hardware_interface/VelocityJointInterface</hardwareInterface>
  </joint>
  <actuator name="Rev49_actr">
    <hardwareInterface>hardware_interface/VelocityJointInterface</hardwareInterface>
    <mechanicalReduction>1</mechanicalReduction>
  </actuator>
</transmission>
-->
  <!--
<transmission name="wheel_joint_front_left_tran">
  <type>transmission_interface/SimpleTransmission</type>
  <joint name="wheel_joint_front_left">
    <hardwareInterface>hardware_interface/VelocityJointInterface</hardwareInterface>
  </joint>
  <actuator name="wheel_joint_front_left_actr">
    <hardwareInterface>hardware_interface/VelocityJointInterface</hardwareInterface>
    <mechanicalReduction>1</mechanicalReduction>
  </actuator>
</transmission>

<transmission name="wheel_joint_back_right_tran">
  <type>transmission_interface/SimpleTransmission</type>
  <joint name="wheel_joint_back_right">
    <hardwareInterface>hardware_interface/VelocityJointInterface</hardwareInterface>
  </joint>
  <actuator name="wheel_joint_back_right_actr">
    <hardwareInterface>hardware_interface/VelocityJointInterface</hardwareInterface>
    <mechanicalReduction>1</mechanicalReduction>
  </actuator>
</transmission>

<transmission name="wheel_joint_front_right_tran">
  <type>transmission_interface/SimpleTransmission</type>
  <joint name="wheel_joint_front_right">
    <hardwareInterface>hardware_interface/VelocityJointInterface</hardwareInterface>
  </joint>
  <actuator name="wheel_joint_front_right_actr">
    <hardwareInterface>hardware_interface/VelocityJointInterface</hardwareInterface>
    <mechanicalReduction>1</mechanicalReduction>
  </actuator>
</transmission>

<transmission name="wheel_joint_back_left_tran">
  <type>transmission_interface/SimpleTransmission</type>
  <joint name="wheel_joint_back_left">
    <hardwareInterface>hardware_interface/VelocityJointInterface</hardwareInterface>
  </joint>
  <actuator name="wheel_joint_back_left_actr">
    <hardwareInterface>hardware_interface/VelocityJointInterface</hardwareInterface>
    <mechanicalReduction>1</mechanicalReduction>
  </actuator>
</transmission>
-->
  <transmission name="arm_base_joint_tran">
    <type>transmission_interface/SimpleTransmission</type>
    <joint name="arm_base_joint">
      <hardwareInterface>hardware_interface/VelocityJointInterface</hardwareInterface>
    </joint>
    <actuator name="arm_base_joint_actr">
      <hardwareInterface>hardware_interface/VelocityJointInterface</hardwareInterface>
      <mechanicalReduction>1</mechanicalReduction>
    </actuator>
  </transmission>
  <!--
<transmission name="camera_revolute_tran">
  <type>transmission_interface/SimpleTransmission</type>
  <joint name="camera_revolute">
    <hardwareInterface>hardware_interface/VelocityJointInterface</hardwareInterface>
  </joint>
  <actuator name="camera_revolute_actr">
    <hardwareInterface>hardware_interface/VelocityJointInterface</hardwareInterface>
    <mechanicalReduction>1</mechanicalReduction>
  </actuator>
</transmission>
-->
  <gazebo>
    <plugin filename="libgazebo_ros_control.so" name="gazebo_ros_control">
      <robotNamespace>/robot</robotNamespace>
      <robotSimType>gazebo_ros_control/DefaultRobotHWSim</robotSimType>
    </plugin>
  </gazebo>
  <gazebo>
    <plugin filename="libnexus_ros_force_based_move.so" name="nexus_ros_force_based_move">
      <commandTopic>cmd_vel</commandTopic>
      <odometryTopic>odom</odometryTopic>
      <odometryFrame>odom</odometryFrame>
      <odometryRate>25.0</odometryRate>
      <robotBaseFrame>base_frame</robotBaseFrame>
      <cmdVelTimeOut>0.25</cmdVelTimeOut>
      <publishOdometryTf>0</publishOdometryTf>
      <yaw_velocity_p_gain>100.0</yaw_velocity_p_gain>
      <x_velocity_p_gain>150.0</x_velocity_p_gain>
      <y_velocity_p_gain>150.0</y_velocity_p_gain>
      <max_x_velocity>10.0</max_x_velocity>
      <max_y_velocity>10.0</max_y_velocity>
      <max_yaw_velocity>5.0</max_yaw_velocity>
    </plugin>
  </gazebo>
  <gazebo reference="dummy">
    <gravity>true</gravity>
  </gazebo>
  <gazebo reference="base_link">
    <material>Gazebo/Silver</material>
    <mu1>0.2</mu1>
    <mu2>0.2</mu2>
    <selfCollide>true</selfCollide>
  </gazebo>
  <gazebo reference="arm_base_1">
    <material>Gazebo/Silver</material>
    <mu1>0.2</mu1>
    <mu2>0.2</mu2>
    <selfCollide>true</selfCollide>
  </gazebo>
  <gazebo reference="stepper_joint_1">
    <material>Gazebo/Silver</material>
    <mu1>0.2</mu1>
    <mu2>0.2</mu2>
    <selfCollide>true</selfCollide>
  </gazebo>
  <gazebo reference="link_1_1">
    <material>Gazebo/Silver</material>
    <mu1>0.2</mu1>
    <mu2>0.2</mu2>
    <selfCollide>true</selfCollide>
  </gazebo>
  <gazebo reference="link_2_1">
    <material>Gazebo/Silver</material>
    <mu1>0.2</mu1>
    <mu2>0.2</mu2>
    <selfCollide>true</selfCollide>
  </gazebo>
  <gazebo reference="link_3_1">
    <material>Gazebo/Silver</material>
    <mu1>0.2</mu1>
    <mu2>0.2</mu2>
    <selfCollide>true</selfCollide>
  </gazebo>
  <gazebo reference="link_end_1">
    <material>Gazebo/Silver</material>
    <mu1>0.2</mu1>
    <mu2>0.2</mu2>
    <selfCollide>true</selfCollide>
  </gazebo>
  <gazebo reference="NEMA_24_2_1">
    <material>Gazebo/Silver</material>
    <mu1>0.2</mu1>
    <mu2>0.2</mu2>
    <selfCollide>true</selfCollide>
  </gazebo>
  <gazebo reference="NEMA_24_3_1">
    <material>Gazebo/Silver</material>
    <mu1>0.2</mu1>
    <mu2>0.2</mu2>
    <selfCollide>true</selfCollide>
  </gazebo>
  <gazebo reference="NEMA_24_4_1">
    <material>Gazebo/Silver</material>
    <mu1>0.2</mu1>
    <mu2>0.2</mu2>
    <selfCollide>true</selfCollide>
  </gazebo>
  <gazebo reference="modified_gripper_v3_1">
    <material>Gazebo/Silver</material>
    <mu1>0.2</mu1>
    <mu2>0.2</mu2>
    <selfCollide>true</selfCollide>
  </gazebo>
  <gazebo reference="finger_1_1">
    <material>Gazebo/Silver</material>
    <mu1>0.0</mu1>
    <mu2>0.0</mu2>
    <selfCollide>true</selfCollide>
  </gazebo>
  <gazebo reference="finger_2_1">
    <material>Gazebo/Silver</material>
    <mu1>0.0</mu1>
    <mu2>0.0</mu2>
    <selfCollide>true</selfCollide>
  </gazebo>
  <gazebo reference="camera_stuff_MODIFIED_camera_pitch_rotation_stand_v1_1">
    <material>Gazebo/Silver</material>
    <mu1>0.2</mu1>
    <mu2>0.2</mu2>
    <selfCollide>true</selfCollide>
  </gazebo>
  <gazebo reference="camera_stuff_MODIFIED_camera_pitch_rotation_base_v1_1">
    <material>Gazebo/Silver</material>
    <mu1>0.2</mu1>
    <mu2>0.2</mu2>
    <selfCollide>true</selfCollide>
  </gazebo>
  <gazebo reference="wheel_front_left_1">
    <material>Gazebo/Silver</material>
    <mu1>0.0</mu1>
    <mu2>0.0</mu2>
    <selfCollide>true</selfCollide>
  </gazebo>
  <gazebo reference="wheel_back_right_1">
    <material>Gazebo/Silver</material>
    <mu1>0.0</mu1>
    <mu2>0.0</mu2>
    <selfCollide>true</selfCollide>
  </gazebo>
  <gazebo reference="wheel_front_right_1">
    <material>Gazebo/Silver</material>
    <mu1>0.0</mu1>
    <mu2>0.0</mu2>
    <selfCollide>true</selfCollide>
  </gazebo>
  <gazebo reference="wheel_back_left_1">
    <material>Gazebo/Silver</material>
    <mu1>0.0</mu1>
    <mu2>0.0</mu2>
    <selfCollide>true</selfCollide>
  </gazebo>
  <gazebo reference="nylon_platform_1">
    <material>Gazebo/Silver</material>
    <mu1>0.2</mu1>
    <mu2>0.2</mu2>
    <selfCollide>true</selfCollide>
  </gazebo>
  <gazebo reference="base_turnable_1">
    <material>Gazebo/Silver</material>
    <mu1>0.2</mu1>
    <mu2>0.2</mu2>
    <selfCollide>true</selfCollide>
  </gazebo>
  <gazebo reference="NEMA_34_1">
    <material>Gazebo/Silver</material>
    <mu1>0.2</mu1>
    <mu2>0.2</mu2>
    <selfCollide>true</selfCollide>
  </gazebo>
  <gazebo reference="RealSense_Camera_1">
    <material>Gazebo/Silver</material>
    <mu1>0.2</mu1>
    <mu2>0.2</mu2>
    <selfCollide>true</selfCollide>
  </gazebo>
  <gazebo reference="NEMA_24_1_1">
    <material>Gazebo/Silver</material>
    <mu1>0.2</mu1>
    <mu2>0.2</mu2>
    <selfCollide>true</selfCollide>
  </gazebo>
  <gazebo reference="DistanceSensor_front_1">
    <material>Gazebo/Silver</material>
    <mu1>0.2</mu1>
    <mu2>0.2</mu2>
    <selfCollide>true</selfCollide>
  </gazebo>
  <gazebo reference="DistanceSensor_left_1">
    <material>Gazebo/Silver</material>
    <mu1>0.2</mu1>
    <mu2>0.2</mu2>
    <selfCollide>true</selfCollide>
  </gazebo>
  <gazebo reference="DistanceSensor_right_1">
    <material>Gazebo/Silver</material>
    <mu1>0.2</mu1>
    <mu2>0.2</mu2>
    <selfCollide>true</selfCollide>
  </gazebo>
  <gazebo reference="DistanceSensor_back_1">
    <material>Gazebo/Silver</material>
    <mu1>0.2</mu1>
    <mu2>0.2</mu2>
    <selfCollide>true</selfCollide>
  </gazebo>
  <link name="base_frame"/>
  <joint name="base_frame_joint" type="fixed">
    <origin rpy="0 0 0" xyz="0 0 0"/>
    <parent link="base_frame"/>
    <child link="base_link"/>
  </joint>
  <link name="base_link">
    <inertial>
      <origin rpy="0 0 0" xyz="-0.00015399363028194057 -0.03925075208016042 0.2644524795806922"/>
      <mass value="31.054157277051146"/>
      <inertia ixx="3.596388" ixy="5e-06" ixz="-0.123996" iyy="5.832947" iyz="8.8e-05" izz="6.339272"/>
    </inertial>
    <visual>
      <origin rpy="0 0 0" xyz="0 0 0"/>
      <geometry>
        <mesh filename="package://robot_description/meshes/base_link.dae" scale="0.001 0.001 0.001"/>
      </geometry>
      <material name="silver"/>
    </visual>
    <collision>
      <origin rpy="0 0 0" xyz="0 0 0"/>
      <geometry>
        <mesh filename="package://robot_description/meshes/base_link.dae" scale="0.001 0.001 0.001"/>
      </geometry>
    </collision>
  </link>
  <link name="arm_base_1">
    <inertial>
      <origin rpy="0 0 0" xyz="-0.10852294745565316 4.764549026911591e-07 0.07021749351752882"/>
      <mass value="2.9829690964186772"/>
      <inertia ixx="0.017973" ixy="0.0" ixz="-0.002884" iyy="0.024074" iyz="0.0" izz="0.02919"/>
    </inertial>
    <visual>
      <origin rpy="0 0 0" xyz="-0.514256 0.039266 -0.595"/>
      <geometry>
        <mesh filename="package://robot_description/meshes/arm_base_1.dae" scale="0.001 0.001 0.001"/>
      </geometry>
      <material name="silver"/>
    </visual>
    <collision>
      <origin rpy="0 0 0" xyz="-0.514256 0.039266 -0.595"/>
      <geometry>
        <mesh filename="package://robot_description/meshes/arm_base_1.dae" scale="0.001 0.001 0.001"/>
      </geometry>
    </collision>
  </link>
  <link name="stepper_joint_1">
    <inertial>
      <origin rpy="0 0 0" xyz="2.341512516101929e-07 -0.007499523545187715 1.1102230246251565e-16"/>
      <mass value="0.10172869711405369"/>
      <inertia ixx="1.1e-05" ixy="0.0" ixz="-0.0" iyy="1.9e-05" iyz="-0.0" izz="1.1e-05"/>
    </inertial>
    <visual>
      <origin rpy="0 0 0" xyz="-0.529256 0.042746 -0.86"/>
      <geometry>
        <mesh filename="package://robot_description/meshes/stepper_joint_1.dae" scale="0.001 0.001 0.001"/>
      </geometry>
      <material name="silver"/>
    </visual>
    <collision>
      <origin rpy="0 0 0" xyz="-0.529256 0.042746 -0.86"/>
      <geometry>
        <mesh filename="package://robot_description/meshes/stepper_joint_1.dae" scale="0.001 0.001 0.001"/>
      </geometry>
    </collision>
  </link>
  <link name="link_1_1">
    <inertial>
      <origin rpy="0 0 0" xyz="0.2614823003165665 0.0075004764548120065 0.0"/>
      <mass value="1.2422891158221263"/>
      <inertia ixx="0.000414" ixy="0.0" ixz="0.0" iyy="0.03033" iyz="0.0" izz="0.029962"/>
    </inertial>
    <visual>
      <origin rpy="0 0 0" xyz="-0.529256 0.042746 -0.86"/>
      <geometry>
        <mesh filename="package://robot_description/meshes/link_1_1.dae" scale="0.001 0.001 0.001"/>
      </geometry>
      <material name="silver"/>
    </visual>
    <collision>
      <origin rpy="0 0 0" xyz="-0.529256 0.042746 -0.86"/>
      <geometry>
        <mesh filename="package://robot_description/meshes/link_1_1.dae" scale="0.001 0.001 0.001"/>
      </geometry>
    </collision>
  </link>
  <link name="link_2_1">
    <inertial>
      <origin rpy="0 0 0" xyz="0.017800019585049176 -0.026213196213553565 0.0"/>
      <mass value="0.8743627585315773"/>
      <inertia ixx="0.000864" ixy="8.4e-05" ixz="0.0" iyy="0.000992" iyz="-0.0" izz="0.001253"/>
    </inertial>
    <visual>
      <origin rpy="0 0 0" xyz="-1.044256 0.042746 -0.86"/>
      <geometry>
        <mesh filename="package://robot_description/meshes/link_2_1.dae" scale="0.001 0.001 0.001"/>
      </geometry>
      <material name="silver"/>
    </visual>
    <collision>
      <origin rpy="0 0 0" xyz="-1.044256 0.042746 -0.86"/>
      <geometry>
        <mesh filename="package://robot_description/meshes/link_2_1.dae" scale="0.001 0.001 0.001"/>
      </geometry>
    </collision>
  </link>
  <link name="link_3_1">
    <inertial>
      <origin rpy="0 0 0" xyz="0.17692244776626231 -0.02499804736277332 3.3306690738754696e-16"/>
      <mass value="1.5478777520934175"/>
      <inertia ixx="0.001209" ixy="0.002603" ixz="-0.0" iyy="0.032303" iyz="0.0" izz="0.032482"/>
    </inertial>
    <visual>
      <origin rpy="0 0 0" xyz="-1.114256 0.077746 -0.86"/>
      <geometry>
        <mesh filename="package://robot_description/meshes/link_3_1.dae" scale="0.001 0.001 0.001"/>
      </geometry>
      <material name="silver"/>
    </visual>
    <collision>
      <origin rpy="0 0 0" xyz="-1.114256 0.077746 -0.86"/>
      <geometry>
        <mesh filename="package://robot_description/meshes/link_3_1.dae" scale="0.001 0.001 0.001"/>
      </geometry>
    </collision>
  </link>
  <link name="link_end_1">
    <inertial>
      <origin rpy="0 0 0" xyz="0.011579352213925143 0.033797262451582544 1.1102230246251565e-16"/>
      <mass value="1.063293416063342"/>
      <inertia ixx="0.00115" ixy="-7.6e-05" ixz="-0.0" iyy="0.000747" iyz="0.0" izz="0.001353"/>
    </inertial>
    <visual>
      <origin rpy="0 0 0" xyz="-1.569256 0.107746 -0.86"/>
      <geometry>
        <mesh filename="package://robot_description/meshes/link_end_1.dae" scale="0.001 0.001 0.001"/>
      </geometry>
      <material name="silver"/>
    </visual>
    <collision>
      <origin rpy="0 0 0" xyz="-1.569256 0.107746 -0.86"/>
      <geometry>
        <mesh filename="package://robot_description/meshes/link_end_1.dae" scale="0.001 0.001 0.001"/>
      </geometry>
    </collision>
  </link>
  <link name="NEMA_24_2_1">
    <inertial>
      <origin rpy="0 0 0" xyz="3.107106621991207e-07 -0.04795031839924011 2.5568133203979215e-06"/>
      <mass value="2.4982959259379585"/>
      <inertia ixx="0.002718" ixy="0.0" ixz="0.0" iyy="0.001293" iyz="0.0" izz="0.002718"/>
    </inertial>
    <visual>
      <origin rpy="0 0 0" xyz="-0.666756 0.042746 -0.86"/>
      <geometry>
        <mesh filename="package://robot_description/meshes/NEMA_24_2_1.dae" scale="0.001 0.001 0.001"/>
      </geometry>
      <material name="silver"/>
    </visual>
    <collision>
      <origin rpy="0 0 0" xyz="-0.666756 0.042746 -0.86"/>
      <geometry>
        <mesh filename="package://robot_description/meshes/NEMA_24_2_1.dae" scale="0.001 0.001 0.001"/>
      </geometry>
    </collision>
  </link>
  <link name="NEMA_24_3_1">
    <inertial>
      <origin rpy="0 0 0" xyz="-0.04744967584155013 4.039331734789764e-07 3.008172847374091e-06"/>
      <mass value="0.9071303592190116"/>
      <inertia ixx="0.000445" ixy="-0.0" ixz="0.0" iyy="0.000995" iyz="-0.0" izz="0.000995"/>
    </inertial>
    <visual>
      <origin rpy="0 0 0" xyz="-1.014256 0.077746 -0.86"/>
      <geometry>
        <mesh filename="package://robot_description/meshes/NEMA_24_3_1.dae" scale="0.001 0.001 0.001"/>
      </geometry>
      <material name="silver"/>
    </visual>
    <collision>
      <origin rpy="0 0 0" xyz="-1.014256 0.077746 -0.86"/>
      <geometry>
        <mesh filename="package://robot_description/meshes/NEMA_24_3_1.dae" scale="0.001 0.001 0.001"/>
      </geometry>
    </collision>
  </link>
  <link name="NEMA_24_4_1">
    <inertial>
      <origin rpy="0 0 0" xyz="0.0014503241584495896 5.489764498406435e-07 -0.029803008172847645"/>
      <mass value="0.9071303592190116"/>
      <inertia ixx="0.000445" ixy="0.0" ixz="-0.0" iyy="0.000995" iyz="-0.0" izz="0.000995"/>
    </inertial>
    <visual>
      <origin rpy="0 0 0" xyz="-1.064256 0.075246 -0.83"/>
      <geometry>
        <mesh filename="package://robot_description/meshes/NEMA_24_4_1.dae" scale="0.001 0.001 0.001"/>
      </geometry>
      <material name="silver"/>
    </visual>
    <collision>
      <origin rpy="0 0 0" xyz="-1.064256 0.075246 -0.83"/>
      <geometry>
        <mesh filename="package://robot_description/meshes/NEMA_24_4_1.dae" scale="0.001 0.001 0.001"/>
      </geometry>
    </collision>
  </link>
  <!--
<link name="gripper_base_1">
  <inertial>
    <origin rpy="0 0 0" xyz="0.03673679203693969 4.773286157999657e-07 1.1906853281118401e-10"/>
    <mass value="0.3892056116726888"/>
    <inertia ixx="0.000453" ixy="-0.0" ixz="-0.0" iyy="0.000387" iyz="0.0" izz="0.000387"/>
  </inertial>
  <visual>
    <origin rpy="0 0 0" xyz="-1.619256 0.067746 -0.86"/>
    <geometry>
      <mesh filename="package://robot_description/meshes/gripper_base_1.dae" scale="0.001 0.001 0.001"/>
    </geometry>
    <material name="silver"/>
  </visual>
  <collision>
    <origin rpy="0 0 0" xyz="-1.619256 0.067746 -0.86"/>
    <geometry>
      <mesh filename="package://robot_description/meshes/gripper_base_1.dae" scale="0.001 0.001 0.001"/>
    </geometry>
  </collision>
</link>

<link name="gripper_finger_1_1">
  <inertial>
    <origin rpy="0 0 0" xyz="0.022980202741784472 4.7678311926313555e-07 0.0048653337708142175"/>
    <mass value="0.025835822102978977"/>
    <inertia ixx="1e-06" ixy="-0.0" ixz="-0.0" iyy="6e-06" iyz="0.0" izz="6e-06"/>
  </inertial>
  <visual>
    <origin rpy="0 0 0" xyz="-1.703756 0.067746 -0.8925"/>
    <geometry>
      <mesh filename="package://robot_description/meshes/gripper_finger_1_1.dae" scale="0.001 0.001 0.001"/>
    </geometry>
    <material name="silver"/>
  </visual>
  <collision>
    <origin rpy="0 0 0" xyz="-1.703756 0.067746 -0.8925"/>
    <geometry>
      <mesh filename="package://robot_description/meshes/gripper_finger_1_1.dae" scale="0.001 0.001 0.001"/>
    </geometry>
  </collision>
</link>

<link name="gripper_finger_2_1">
  <inertial>
    <origin rpy="0 0 0" xyz="0.02298020274178514 -0.004213851845047717 -0.0024326668274717855"/>
    <mass value="0.025835822102978977"/>
    <inertia ixx="1e-06" ixy="0.0" ixz="0.0" iyy="6e-06" iyz="0.0" izz="6e-06"/>
  </inertial>
  <visual>
    <origin rpy="0 0 0" xyz="-1.703756 0.095891 -0.84375"/>
    <geometry>
      <mesh filename="package://robot_description/meshes/gripper_finger_2_1.dae" scale="0.001 0.001 0.001"/>
    </geometry>
    <material name="silver"/>
  </visual>
  <collision>
    <origin rpy="0 0 0" xyz="-1.703756 0.095891 -0.84375"/>
    <geometry>
      <mesh filename="package://robot_description/meshes/gripper_finger_2_1.dae" scale="0.001 0.001 0.001"/>
    </geometry>
  </collision>
</link>

<link name="gripper_finger_3_1">
  <inertial>
    <origin rpy="0 0 0" xyz="0.02298020274178514 0.004213804557066415 -0.0024326671697302293"/>
    <mass value="0.025835822102978977"/>
    <inertia ixx="1e-06" ixy="-0.0" ixz="0.0" iyy="6e-06" iyz="-0.0" izz="6e-06"/>
  </inertial>
  <visual>
    <origin rpy="0 0 0" xyz="-1.703756 0.0396 -0.84375"/>
    <geometry>
      <mesh filename="package://robot_description/meshes/gripper_finger_3_1.dae" scale="0.001 0.001 0.001"/>
    </geometry>
    <material name="silver"/>
  </visual>
  <collision>
    <origin rpy="0 0 0" xyz="-1.703756 0.0396 -0.84375"/>
    <geometry>
      <mesh filename="package://robot_description/meshes/gripper_finger_3_1.dae" scale="0.001 0.001 0.001"/>
    </geometry>
  </collision>
</link>


-->
  <!--WHEELS-->
  <link name="wheel_front_left_1">
    <inertial>
      <origin rpy="0 0 0" xyz="4.432951922206385e-07 -0.02746282748166934 -1.346983284356007e-07"/>
      <mass value="1.1212840703003284"/>
      <inertia ixx="0.002009" ixy="0.0" ixz="0.0" iyy="0.003227" iyz="-0.0" izz="0.002009"/>
    </inertial>
    <visual>
      <origin rpy="0 0 0" xyz="-0.389785 -0.351556 -0.072882"/>
      <geometry>
        <mesh filename="package://robot_description/meshes/wheel_front_left_1.dae" scale="0.001 0.001 0.001"/>
      </geometry>
      <material name="silver"/>
    </visual>
    <collision>
      <!--origin rpy="0 0 0" xyz="-0.389785 -0.351556 -0.072882"/>
    <geometry>
      <mesh filename="package://robot_description/meshes/wheel_front_left_1.dae" scale="0.001 0.001 0.001"/>
    </geometry-->
      <origin rpy="1.57 0 0" xyz="0 -0.025 0"/>
      <geometry>
        <cylinder length="0.05" radius="0.075"/>
      </geometry>
    </collision>
  </link>
  <link name="wheel_back_right_1">
    <inertial>
      <origin rpy="0 0 0" xyz="-1.2505490770697847e-07 0.02746359966411499 -1.3465862684636232e-07"/>
      <mass value="1.121282907418049"/>
      <inertia ixx="0.002009" ixy="0.0" ixz="-0.0" iyy="0.003227" iyz="0.0" izz="0.002009"/>
    </inertial>
    <visual>
      <origin rpy="0 0 0" xyz="0.399993 0.429444 -0.072882"/>
      <geometry>
        <mesh filename="package://robot_description/meshes/wheel_back_right_1.dae" scale="0.001 0.001 0.001"/>
      </geometry>
      <material name="silver"/>
    </visual>
    <collision>
      <!--origin rpy="0 0 0" xyz="0.399993 0.429444 -0.072882"/>
    <geometry>
      <mesh filename="package://robot_description/meshes/wheel_back_right_1.dae" scale="0.001 0.001 0.001"/>
    </geometry-->
      <origin rpy="1.57 0 0" xyz="0 0.025 0"/>
      <geometry>
        <cylinder length="0.05" radius="0.075"/>
      </geometry>
    </collision>
  </link>
  <link name="wheel_front_right_1">
    <inertial>
      <origin rpy="0 0 0" xyz="-1.260755462806351e-07 0.027463574797679857 -1.3559114592220922e-07"/>
      <mass value="1.121283635279382"/>
      <inertia ixx="0.002009" ixy="0.0" ixz="-0.0" iyy="0.003227" iyz="0.0" izz="0.002009"/>
    </inertial>
    <visual>
      <origin rpy="0 0 0" xyz="-0.390007 0.429444 -0.072882"/>
      <geometry>
        <mesh filename="package://robot_description/meshes/wheel_front_right_1.dae" scale="0.001 0.001 0.001"/>
      </geometry>
      <material name="silver"/>
    </visual>
    <collision>
      <!--origin rpy="0 0 0" xyz="-0.390007 0.429444 -0.072882"/>
    <geometry>
      <mesh filename="package://robot_description/meshes/wheel_front_right_1.dae" scale="0.001 0.001 0.001"/>
    </geometry-->
      <origin rpy="1.57 0 0" xyz="0 0.025 0"/>
      <geometry>
        <cylinder length="0.05" radius="0.075"/>
      </geometry>
    </collision>
  </link>
  <link name="wheel_back_left_1">
    <inertial>
      <origin rpy="0 0 0" xyz="4.4379789443382833e-07 -0.02746283333611338 -1.3537967641363835e-07"/>
      <mass value="1.1212813837583047"/>
      <inertia ixx="0.002009" ixy="-0.0" ixz="0.0" iyy="0.003227" iyz="-0.0" izz="0.002009"/>
    </inertial>
    <visual>
      <origin rpy="0 0 0" xyz="0.400215 -0.351556 -0.072882"/>
      <geometry>
        <mesh filename="package://robot_description/meshes/wheel_back_left_1.dae" scale="0.001 0.001 0.001"/>
      </geometry>
      <material name="silver"/>
    </visual>
    <collision>
      <!--origin rpy="0 0 0" xyz="0.400215 -0.351556 -0.072882"/>
    <geometry>
      <mesh filename="package://robot_description/meshes/wheel_back_left_1.dae" scale="0.001 0.001 0.001"/>
    </geometry-->
      <origin rpy="1.57 0 0" xyz="0 -0.025 0"/>
      <geometry>
        <cylinder length="0.05" radius="0.075"/>
      </geometry>
    </collision>
  </link>
  <link name="nylon_platform_1">
    <inertial>
      <origin rpy="0 0 0" xyz="1.5062866637327588e-07 4.7645481348473906e-07 0.003175431748572266"/>
      <mass value="2.1524166451200006"/>
      <inertia ixx="0.065097" ixy="-0.0" ixz="0.0" iyy="0.045281" iyz="-0.0" izz="0.110364"/>
    </inertial>
    <visual>
      <origin rpy="0 0 0" xyz="0.242882 0.039266 -0.283202"/>
      <geometry>
        <mesh filename="package://robot_description/meshes/nylon_platform_1.dae" scale="0.001 0.001 0.001"/>
      </geometry>
      <material name="silver"/>
    </visual>
    <collision>
      <origin rpy="0 0 0" xyz="0.242882 0.039266 -0.283202"/>
      <geometry>
        <mesh filename="package://robot_description/meshes/nylon_platform_1.dae" scale="0.001 0.001 0.001"/>
      </geometry>
    </collision>
  </link>
  <link name="base_turnable_1">
    <inertial>
      <origin rpy="0 0 0" xyz="0.0054287840120818 0.019681365316078368 0.023506450840144688"/>
      <mass value="6.27904528107532"/>
      <inertia ixx="0.115631" ixy="0.000233" ixz="-0.002428" iyy="0.109757" iyz="-0.021421" izz="0.018856"/>
    </inertial>
    <visual>
      <origin rpy="0 0 0" xyz="-0.439256 0.039266 -0.775"/>
      <geometry>
        <mesh filename="package://robot_description/meshes/base_turnable_1.dae" scale="0.001 0.001 0.001"/>
      </geometry>
      <material name="silver"/>
    </visual>
    <collision>
      <origin rpy="0 0 0" xyz="-0.439256 0.039266 -0.775"/>
      <geometry>
        <mesh filename="package://robot_description/meshes/base_turnable_1.dae" scale="0.001 0.001 0.001"/>
      </geometry>
    </collision>
  </link>
  <link name="NEMA_34_1">
    <inertial>
      <origin rpy="0 0 0" xyz="-1.8231621852216051e-06 -0.07677876842578721 -1.1102230246251565e-16"/>
      <mass value="8.323733041924031"/>
      <inertia ixx="0.021977" ixy="2e-06" ixz="0.0" iyy="0.008997" iyz="0.0" izz="0.021977"/>
    </inertial>
    <visual>
      <origin rpy="0 0 0" xyz="-0.529256 0.079266 -0.86"/>
      <geometry>
        <mesh filename="package://robot_description/meshes/NEMA_34_1.dae" scale="0.001 0.001 0.001"/>
      </geometry>
      <material name="silver"/>
    </visual>
    <collision>
      <origin rpy="0 0 0" xyz="-0.529256 0.079266 -0.86"/>
      <geometry>
        <mesh filename="package://robot_description/meshes/NEMA_34_1.dae" scale="0.001 0.001 0.001"/>
      </geometry>
    </collision>
  </link>
  <!--
<link name="RealSense_Camera_1">
  <inertial>
    <origin rpy="0 0 0" xyz="0.001044234578889247 0.0010700784612081293 0.01201138007609126"/>
    <mass value="0.03698911171124503"/>
    <inertia ixx="2.4e-05" ixy="0.0" ixz="0.0" iyy="3e-06" iyz="-0.0" izz="2.4e-05"/>
  </inertial>
  <visual>
    <origin rpy="0 0 0" xyz="-0.444256 -0.050734 -1.404827"/>
    <geometry>
      <mesh filename="package://robot_description/meshes/RealSense_Camera_1.dae" scale="0.001 0.001 0.001"/>
    </geometry>
    <material name="silver"/>
  </visual>
  <collision>
    <origin rpy="0 0 0" xyz="-0.444256 -0.050734 -1.404827"/>
    <geometry>
      <mesh filename="package://robot_description/meshes/RealSense_Camera_1.dae" scale="0.001 0.001 0.001"/>
    </geometry>
  </collision>
</link>
-->
  <link name="RealSense_Camera_1"/>
  <material name="camera_aluminum">
    <color rgba="0.5 0.5 0.5 1"/>
  </material>
  <!-- camera body, with origin at bottom screw mount -->
  <joint name="camera_joint" type="fixed">
    <origin rpy="0 0 0" xyz="0 0 0"/>
    <parent link="RealSense_Camera_1"/>
    <child link="camera_bottom_screw_frame"/>
  </joint>
  <link name="camera_bottom_screw_frame"/>
  <joint name="camera_link_joint" type="fixed">
    <origin rpy="0 0 0" xyz="0 0.0175 0.0125"/>
    <parent link="camera_bottom_screw_frame"/>
    <child link="camera_link"/>
  </joint>
  <link name="camera_link">
    <visual>
      <origin rpy="1.5707963267948966 0 1.5707963267948966" xyz="0.0149 -0.0175 0"/>
      <geometry>
        <!-- <box size="${d435_cam_width} ${d435_cam_height} ${d435_cam_depth}"/> -->
        <mesh filename="package://robot_description/meshes/d435.dae"/>
        <!--<mesh filename="package://realsense2_description/meshes/d435/d435.dae" />-->
      </geometry>
      <material name="camera_aluminum"/>
    </visual>
    <collision>
      <origin rpy="0 0 0" xyz="0 -0.0175 0"/>
      <geometry>
        <box size="0.02505 0.09 0.025"/>
      </geometry>
    </collision>
    <inertial>
      <!-- The following are not reliable values, and should not be used for modeling -->
      <mass value="0.564"/>
      <origin xyz="0 0 0"/>
      <inertia ixx="0.003881243" ixy="0.0" ixz="0.0" iyy="0.000498940" iyz="0.0" izz="0.003879257"/>
    </inertial>
  </link>
  <!-- camera depth joints and links -->
  <joint name="camera_depth_joint" type="fixed">
    <origin rpy="0 0 0" xyz="0 0 0"/>
    <parent link="camera_link"/>
    <child link="camera_depth_frame"/>
  </joint>
  <link name="camera_depth_frame"/>
  <joint name="camera_depth_optical_joint" type="fixed">
    <origin rpy="-1.5707963267948966 0 -1.5707963267948966" xyz="0 0 0"/>
    <parent link="camera_depth_frame"/>
    <child link="camera_depth_optical_frame"/>
  </joint>
  <link name="camera_depth_optical_frame"/>
  <!-- camera left IR joints and links -->
  <joint name="camera_left_ir_joint" type="fixed">
    <origin rpy="0 0 0" xyz="0 0.0 0"/>
    <parent link="camera_depth_frame"/>
    <child link="camera_left_ir_frame"/>
  </joint>
  <link name="camera_left_ir_frame"/>
  <joint name="camera_left_ir_optical_joint" type="fixed">
    <origin rpy="-1.5707963267948966 0 -1.5707963267948966" xyz="0 0 0"/>
    <parent link="camera_left_ir_frame"/>
    <child link="camera_left_ir_optical_frame"/>
  </joint>
  <link name="camera_left_ir_optical_frame"/>
  <!-- camera right IR joints and links -->
  <joint name="camera_right_ir_joint" type="fixed">
    <origin rpy="0 0 0" xyz="0 -0.05 0"/>
    <parent link="camera_depth_frame"/>
    <child link="camera_right_ir_frame"/>
  </joint>
  <link name="camera_right_ir_frame"/>
  <joint name="camera_right_ir_optical_joint" type="fixed">
    <origin rpy="-1.5707963267948966 0 -1.5707963267948966" xyz="0 0 0"/>
    <parent link="camera_right_ir_frame"/>
    <child link="camera_right_ir_optical_frame"/>
  </joint>
  <link name="camera_right_ir_optical_frame"/>
  <!-- camera color joints and links -->
  <joint name="camera_color_joint" type="fixed">
    <origin rpy="0 0 0" xyz="0 0.015 0"/>
    <parent link="camera_depth_frame"/>
    <child link="camera_color_frame"/>
  </joint>
  <link name="camera_color_frame"/>
  <joint name="camera_color_optical_joint" type="fixed">
    <origin rpy="-1.5707963267948966 0 -1.5707963267948966" xyz="0 0 0"/>
    <parent link="camera_color_frame"/>
    <child link="camera_color_optical_frame"/>
  </joint>
  <link name="camera_color_optical_frame"/>
  <gazebo reference="camera_link">
    <self_collide>0</self_collide>
    <enable_wind>0</enable_wind>
    <kinematic>0</kinematic>
    <gravity>1</gravity>
    <!--<mu>1</mu>-->
    <mu2>1</mu2>
    <fdir1>0 0 0</fdir1>
    <!--<slip1>0</slip1>
      <slip2>0</slip2>-->
    <kp>1e+13</kp>
    <kd>1</kd>
    <!--<max_vel>0.01</max_vel>
      <min_depth>0</min_depth>-->
    <sensor name="cameracolor" type="camera">
      <camera name="camera">
        <horizontal_fov>1.2112585008840648</horizontal_fov>
        <image>
          <width>1920</width>
          <height>1080</height>
          <format>RGB_INT8</format>
        </image>
        <clip>
          <near>0.1</near>
          <far>100</far>
        </clip>
        <noise>
          <type>gaussian</type>
          <mean>0.0</mean>
          <stddev>0.007</stddev>
        </noise>
      </camera>
      <always_on>1</always_on>
      <update_rate>15</update_rate>
      <visualize>1</visualize>
    </sensor>
    <sensor name="cameraired1" type="camera">
      <camera name="camera">
        <horizontal_fov>1.4870205226991688</horizontal_fov>
        <image>
          <width>1280</width>
          <height>720</height>
          <format>L_INT8</format>
        </image>
        <clip>
          <near>0.1</near>
          <far>100</far>
        </clip>
        <noise>
          <type>gaussian</type>
          <mean>0.0</mean>
          <stddev>0.05</stddev>
        </noise>
      </camera>
      <always_on>1</always_on>
      <update_rate>90</update_rate>
      <visualize>0</visualize>
    </sensor>
    <sensor name="cameraired2" type="camera">
      <camera name="camera">
        <horizontal_fov>1.4870205226991688</horizontal_fov>
        <image>
          <width>1280</width>
          <height>720</height>
          <format>L_INT8</format>
        </image>
        <clip>
          <near>0.1</near>
          <far>100</far>
        </clip>
        <noise>
          <type>gaussian</type>
          <mean>0.0</mean>
          <stddev>0.05</stddev>
        </noise>
      </camera>
      <always_on>1</always_on>
      <update_rate>90</update_rate>
      <visualize>0</visualize>
    </sensor>
    <sensor name="cameradepth" type="depth">
      <camera name="camera">
        <horizontal_fov>1.4870205226991688</horizontal_fov>
        <image>
          <width>1280</width>
          <height>720</height>
        </image>
        <clip>
          <near>0.1</near>
          <far>100</far>
        </clip>
        <noise>
          <type>gaussian</type>
          <mean>0.0</mean>
          <stddev>0.100</stddev>
        </noise>
      </camera>
      <always_on>1</always_on>
      <update_rate>90</update_rate>
      <visualize>0</visualize>
    </sensor>
  </gazebo>
  <gazebo>
    <plugin filename="librealsense_gazebo_plugin.so" name="camera">
      <prefix>camera</prefix>
      <depthUpdateRate>60.0</depthUpdateRate>
      <colorUpdateRate>60.0</colorUpdateRate>
      <infraredUpdateRate>60.0</infraredUpdateRate>
      <depthTopicName>depth/image_raw</depthTopicName>
      <depthCameraInfoTopicName>depth/camera_info</depthCameraInfoTopicName>
      <colorTopicName>color/image_raw</colorTopicName>
      <colorCameraInfoTopicName>color/camera_info</colorCameraInfoTopicName>
      <infrared1TopicName>infra1/image_raw</infrared1TopicName>
      <infrared1CameraInfoTopicName>infra1/camera_info</infrared1CameraInfoTopicName>
      <infrared2TopicName>infra2/image_raw</infrared2TopicName>
      <infrared2CameraInfoTopicName>infra2/camera_info</infrared2CameraInfoTopicName>
      <colorOpticalframeName>camera_color_optical_frame</colorOpticalframeName>
      <depthOpticalframeName>camera_depth_optical_frame</depthOpticalframeName>
      <infrared1OpticalframeName>camera_left_ir_optical_frame</infrared1OpticalframeName>
      <infrared2OpticalframeName>camera_right_ir_optical_frame</infrared2OpticalframeName>
      <rangeMinDepth>0.2</rangeMinDepth>
      <rangeMaxDepth>10.0</rangeMaxDepth>
      <pointCloud>true</pointCloud>
      <pointCloudTopicName>depth/points</pointCloudTopicName>
      <pointCloudCutoff>0.5</pointCloudCutoff>
    </plugin>
  </gazebo>
  <link name="NEMA_24_1_1">
    <inertial>
      <origin rpy="0 0 0" xyz="3.1071066247667645e-07 3.0332681329736655e-06 0.04795079485405218"/>
      <mass value="2.4982959259379585"/>
      <inertia ixx="0.002718" ixy="0.0" ixz="-0.0" iyy="0.002718" iyz="-0.0" izz="0.001293"/>
    </inertial>
    <visual>
      <origin rpy="0 0 0" xyz="-0.314256 0.039266 -0.655"/>
      <geometry>
        <mesh filename="package://robot_description/meshes/NEMA_24_1_1.dae" scale="0.001 0.001 0.001"/>
      </geometry>
      <material name="silver"/>
    </visual>
    <collision>
      <origin rpy="0 0 0" xyz="-0.314256 0.039266 -0.655"/>
      <geometry>
        <mesh filename="package://robot_description/meshes/NEMA_24_1_1.dae" scale="0.001 0.001 0.001"/>
      </geometry>
    </collision>
  </link>
  <link name="DistanceSensor_front_1">
    <inertial>
      <origin rpy="0 0 0" xyz="0.006339069045313783 0.00018607602978239907 -0.00029784821062121825"/>
      <mass value="0.07929512168525539"/>
      <inertia ixx="2e-05" ixy="-0.0" ixz="-0.0" iyy="7e-06" iyz="-0.0" izz="1.8e-05"/>
    </inertial>
    <visual>
      <origin rpy="0 0 0" xyz="-0.514256 0.039266 -0.051064"/>
      <geometry>
        <mesh filename="package://robot_description/meshes/DistanceSensor_front_1.dae" scale="0.001 0.001 0.001"/>
      </geometry>
      <material name="silver"/>
    </visual>
    <collision>
      <origin rpy="0 0 0" xyz="-0.514256 0.039266 -0.051064"/>
      <geometry>
        <mesh filename="package://robot_description/meshes/DistanceSensor_front_1.dae" scale="0.001 0.001 0.001"/>
      </geometry>
    </collision>
  </link>
  <link name="DistanceSensor_left_1">
    <inertial>
      <origin rpy="0 0 0" xyz="-0.00018536542384783947 0.006339311349005006 -0.0002986765042564121"/>
      <mass value="0.07929512168525539"/>
      <inertia ixx="7e-06" ixy="0.0" ixz="0.0" iyy="2e-05" iyz="-0.0" izz="1.8e-05"/>
    </inertial>
    <visual>
      <origin rpy="0 0 0" xyz="0.004794 -0.279784 -0.048649"/>
      <geometry>
        <mesh filename="package://robot_description/meshes/DistanceSensor_left_1.dae" scale="0.001 0.001 0.001"/>
      </geometry>
      <material name="silver"/>
    </visual>
    <collision>
      <origin rpy="0 0 0" xyz="0.004794 -0.279784 -0.048649"/>
      <geometry>
        <mesh filename="package://robot_description/meshes/DistanceSensor_left_1.dae" scale="0.001 0.001 0.001"/>
      </geometry>
    </collision>
  </link>
  <link name="DistanceSensor_right_1">
    <inertial>
      <origin rpy="0 0 0" xyz="0.00018583372609121736 -0.006338358439378855 -0.0002986765042564815"/>
      <mass value="0.07929512168525539"/>
      <inertia ixx="7e-06" ixy="0.0" ixz="-0.0" iyy="2e-05" iyz="0.0" izz="1.8e-05"/>
    </inertial>
    <visual>
      <origin rpy="0 0 0" xyz="0.004794 0.358316 -0.048649"/>
      <geometry>
        <mesh filename="package://robot_description/meshes/DistanceSensor_right_1.dae" scale="0.001 0.001 0.001"/>
      </geometry>
      <material name="silver"/>
    </visual>
    <collision>
      <origin rpy="0 0 0" xyz="0.004794 0.358316 -0.048649"/>
      <geometry>
        <mesh filename="package://robot_description/meshes/DistanceSensor_right_1.dae" scale="0.001 0.001 0.001"/>
      </geometry>
    </collision>
  </link>
  <link name="DistanceSensor_back_1">
    <inertial>
      <origin rpy="0 0 0" xyz="-0.006338600743070466 -0.00018512312015624838 -0.00029784821062114886"/>
      <mass value="0.07929512168525539"/>
      <inertia ixx="2e-05" ixy="-0.0" ixz="0.0" iyy="7e-06" iyz="0.0" izz="1.8e-05"/>
    </inertial>
    <visual>
      <origin rpy="0 0 0" xyz="0.523844 0.039266 -0.051064"/>
      <geometry>
        <mesh filename="package://robot_description/meshes/DistanceSensor_back_1.dae" scale="0.001 0.001 0.001"/>
      </geometry>
      <material name="silver"/>
    </visual>
    <collision>
      <origin rpy="0 0 0" xyz="0.523844 0.039266 -0.051064"/>
      <geometry>
        <mesh filename="package://robot_description/meshes/DistanceSensor_back_1.dae" scale="0.001 0.001 0.001"/>
      </geometry>
    </collision>
  </link>
  <!-- ADD ONS-->
  <link name="modified_gripper_v3_1">
    <inertial>
      <origin rpy="0 0 0" xyz="0.02896330445643147 4.7645481737745854e-07 -1.1102230246251565e-16"/>
      <mass value="0.7210057123672229"/>
      <inertia ixx="0.000522" ixy="-0.0" ixz="0.0" iyy="0.000438" iyz="0.0" izz="0.000507"/>
    </inertial>
    <visual>
      <origin rpy="0 0 0" xyz="-1.619256 0.067746 -0.86"/>
      <geometry>
        <mesh filename="package://robot_description/meshes/modified_gripper_v3_1.stl" scale="0.001 0.001 0.001"/>
      </geometry>
      <material name="silver"/>
    </visual>
    <collision>
      <origin rpy="0 0 0" xyz="-1.619256 0.067746 -0.86"/>
      <geometry>
        <mesh filename="package://robot_description/meshes/modified_gripper_v3_1.stl" scale="0.001 0.001 0.001"/>
      </geometry>
    </collision>
  </link>
  <!--MODIFIED FINGERS-->
  <link name="finger_1_1">
    <inertial>
      <origin rpy="0 0 0" xyz="0.02263618038322157 -0.0016778710854973566 2.9802338374906867e-10"/>
      <mass value="0.017395172706082648"/>
      <inertia ixx="1e-06" ixy="0.0" ixz="0.0" iyy="4e-06" iyz="0.0" izz="4e-06"/>
    </inertial>
    <visual>
      <origin rpy="0 0 0" xyz="-1.703756 0.100246 -0.86"/>
      <geometry>
        <mesh filename="package://robot_description/meshes/finger_1_1.stl" scale="0.001 0.001 0.001"/>
      </geometry>
      <material name="silver"/>
    </visual>
    <collision>
      <origin rpy="0 0 0" xyz="-1.703756 0.100246 -0.86"/>
      <geometry>
        <mesh filename="package://robot_description/meshes/finger_1_1.stl" scale="0.001 0.001 0.001"/>
      </geometry>
    </collision>
  </link>
  <link name="finger_2_1">
    <inertial>
      <origin rpy="0 0 0" xyz="0.022636180383206472 0.001678823995166355 -2.9802316170446375e-10"/>
      <mass value="0.017395172706082648"/>
      <inertia ixx="1e-06" ixy="-0.0" ixz="-0.0" iyy="4e-06" iyz="0.0" izz="4e-06"/>
    </inertial>
    <visual>
      <origin rpy="0 0 0" xyz="-1.703756 0.035246 -0.86"/>
      <geometry>
        <mesh filename="package://robot_description/meshes/finger_2_1.stl" scale="0.001 0.001 0.001"/>
      </geometry>
      <material name="silver"/>
    </visual>
    <collision>
      <origin rpy="0 0 0" xyz="-1.703756 0.035246 -0.86"/>
      <geometry>
        <mesh filename="package://robot_description/meshes/finger_2_1.stl" scale="0.001 0.001 0.001"/>
      </geometry>
    </collision>
  </link>
  <!--changes-->
  <link name="camera_stuff_MODIFIED_camera_pitch_rotation_stand_v1_1">
    <inertial>
      <origin rpy="0 0 0" xyz="-1.7230276102175868e-05 -8.581321605388714e-08 0.013886903161764108"/>
      <mass value="0.14013559068395626"/>
      <inertia ixx="0.00016" ixy="-0.0" ixz="0.0" iyy="2.3e-05" iyz="0.0" izz="0.000141"/>
    </inertial>
    <visual>
      <origin rpy="0 0 0" xyz="-0.443487 -0.050734 -1.403236"/>
      <geometry>
        <mesh filename="package://robot_description/meshes/camera_stuff_MODIFIED_camera_pitch_rotation_stand_v1_1.stl" scale="0.001 0.001 0.001"/>
      </geometry>
      <material name="silver"/>
    </visual>
    <collision>
      <origin rpy="0 0 0" xyz="-0.443487 -0.050734 -1.403236"/>
      <geometry>
        <mesh filename="package://robot_description/meshes/camera_stuff_MODIFIED_camera_pitch_rotation_stand_v1_1.stl" scale="0.001 0.001 0.001"/>
      </geometry>
    </collision>
  </link>
  <link name="camera_stuff_MODIFIED_camera_pitch_rotation_base_v1_1">
    <inertial>
      <origin rpy="0 0 0" xyz="0.00011284358524088489 0.03249927945228931 -0.00023275211680062746"/>
      <mass value="0.12151628240010111"/>
      <inertia ixx="5e-05" ixy="0.0" ixz="-0.0" iyy="5e-06" iyz="-0.0" izz="4.7e-05"/>
    </inertial>
    <visual>
      <origin rpy="0 0 0" xyz="-0.44334 -0.017234 -1.437236"/>
      <geometry>
        <mesh filename="package://robot_description/meshes/camera_stuff_MODIFIED_camera_pitch_rotation_base_v1_1.stl" scale="0.001 0.001 0.001"/>
      </geometry>
      <material name="silver"/>
    </visual>
    <collision>
      <origin rpy="0 0 0" xyz="-0.44334 -0.017234 -1.437236"/>
      <geometry>
        <mesh filename="package://robot_description/meshes/camera_stuff_MODIFIED_camera_pitch_rotation_base_v1_1.stl" scale="0.001 0.001 0.001"/>
      </geometry>
    </collision>
  </link>
  <!-- END OF ADD ONS-->
  <joint name="Rigid1" type="fixed">
    <origin rpy="0 0 0" xyz="0.514256 -0.039266 0.595"/>
    <parent link="base_link"/>
    <child link="arm_base_1"/>
  </joint>
  <joint name="Rigid4" type="fixed">
    <origin rpy="0 0 0" xyz="0.0 0.03652 0.0"/>
    <parent link="NEMA_34_1"/>
    <child link="stepper_joint_1"/>
  </joint>
  <joint name="link_1_joint" type="continuous">
    <origin rpy="0 0 0" xyz="0.0 0.0 0.0"/>
    <parent link="stepper_joint_1"/>
    <child link="link_1_1"/>
    <axis xyz="0.0 1.0 0.0"/>
  </joint>
  <joint name="link_2_joint" type="continuous">
    <origin rpy="0 0 0" xyz="0.515 0.0 0.0"/>
    <parent link="link_1_1"/>
    <child link="link_2_1"/>
    <axis xyz="0.0 1.0 0.0"/>
  </joint>
  <joint name="link_3_joint" type="continuous">
    <origin rpy="0 0 0" xyz="0.07 -0.035 0.0"/>
    <parent link="link_2_1"/>
    <child link="link_3_1"/>
    <axis xyz="-1.0 0.0 -0.0"/>
  </joint>
  <joint name="link_end_joint" type="continuous">
    <origin rpy="0 0 0" xyz="0.455 -0.03 0.0"/>
    <parent link="link_3_1"/>
    <child link="link_end_1"/>
    <axis xyz="-0.0 -1.0 -0.0"/>
  </joint>
  <joint name="Rigid10" type="fixed">
    <origin rpy="0 0 0" xyz="0.1375 0.0 0.0"/>
    <parent link="link_1_1"/>
    <child link="NEMA_24_2_1"/>
  </joint>
  <joint name="Rigid11" type="fixed">
    <origin rpy="0 0 0" xyz="-0.03 -0.035 0.0"/>
    <parent link="link_2_1"/>
    <child link="NEMA_24_3_1"/>
  </joint>
  <joint name="Rigid12" type="fixed">
    <origin rpy="0 0 0" xyz="0.02 -0.0325 -0.03"/>
    <parent link="link_2_1"/>
    <child link="NEMA_24_4_1"/>
  </joint>
  <!--

<joint name="Rigid18" type="fixed">
  <origin rpy="0 0 0" xyz="0.05 0.04 0.0"/>
  <parent link="link_end_1"/>
  <child link="gripper_base_1"/>
</joint>



<joint name="finger_1_joint" type="continuous">
  <origin rpy="0 0 0" xyz="0.0845 0.0 0.0325"/>
  <parent link="gripper_base_1"/>
  <child link="gripper_finger_1_1"/>
  <axis xyz="-0.0 -1.0 -0.0"/>
</joint>

<joint name="finger_2_joint" type="continuous">
  <origin rpy="0 0 0" xyz="0.0845 -0.028145 -0.01625"/>
  <parent link="gripper_base_1"/>
  <child link="gripper_finger_2_1"/>
  <axis xyz="0.0 0.5 -0.866025"/>
</joint>

<joint name="finger_3_joint" type="continuous">
  <origin rpy="0 0 0" xyz="0.0845 0.028146 -0.01625"/>
  <parent link="gripper_base_1"/>
  <child link="gripper_finger_3_1"/>
  <axis xyz="0.0 0.5 0.866025"/>
</joint>

-->
  <!-- MODIFIED PARTS -->
  <joint name="gripper_axis_rev" type="fixed">
    <origin rpy="0 0 0" xyz="0.05 0.04 0.0"/>
    <parent link="link_end_1"/>
    <child link="modified_gripper_v3_1"/>
  </joint>
  <joint name="finger_1_revolute_joint" type="continuous">
    <origin rpy="0 0 0" xyz="0.0845 -0.0325 0.0"/>
    <parent link="modified_gripper_v3_1"/>
    <child link="finger_1_1"/>
    <axis xyz="0.0 0.0 -1.0"/>
  </joint>
  <joint name="finger_2_revolute_joint" type="continuous">
    <origin rpy="0 0 0" xyz="0.0845 0.0325 0.0"/>
    <parent link="modified_gripper_v3_1"/>
    <child link="finger_2_1"/>
    <axis xyz="-0.0 0.0 1.0"/>
  </joint>
  <joint name="camera_yaw_rotation" type="continuous">
    <origin rpy="0 0 0" xyz="0.004109 0.09 0.629833"/>
    <parent link="base_turnable_1"/>
    <child link="camera_stuff_MODIFIED_camera_pitch_rotation_stand_v1_1"/>
    <axis xyz="0.001414 0.0 -0.999999"/>
  </joint>
  <joint name="camera_pitch_rotation" type="continuous">
    <origin rpy="0 0 0" xyz="-0.000147 -0.0335 0.034"/>
    <parent link="camera_stuff_MODIFIED_camera_pitch_rotation_stand_v1_1"/>
    <child link="camera_stuff_MODIFIED_camera_pitch_rotation_base_v1_1"/>
    <axis xyz="0.0 1.0 0.0"/>
  </joint>
  <joint name="Rigid49" type="fixed">
    <!--account for this -->
    <origin rpy="0 0 0" xyz="0.000335 0.032499 0.010001"/>
    <parent link="camera_stuff_MODIFIED_camera_pitch_rotation_base_v1_1"/>
    <child link="RealSense_Camera_1"/>
    <axis xyz="-0.001414 -0.0 0.999999"/>
  </joint>
  <!-- EOF MODIFIED PARTS -->
  <joint name="wheel_joint_front_left" type="continuous">
    <origin rpy="0 0 0" xyz="0.389785 0.351556 0.072882"/>
    <parent link="base_link"/>
    <child link="wheel_front_left_1"/>
    <axis xyz="0.0 -1.0 -0.0"/>
  </joint>
  <joint name="wheel_joint_back_right" type="continuous">
    <origin rpy="0 0 0" xyz="-0.399993 -0.429444 0.072882"/>
    <parent link="base_link"/>
    <child link="wheel_back_right_1"/>
    <axis xyz="0.0 1.0 0.0"/>
  </joint>
  <joint name="wheel_joint_front_right" type="continuous">
    <origin rpy="0 0 0" xyz="0.390007 -0.429444 0.072882"/>
    <parent link="base_link"/>
    <child link="wheel_front_right_1"/>
    <axis xyz="0.0 1.0 0.0"/>
  </joint>
  <joint name="wheel_joint_back_left" type="continuous">
    <origin rpy="0 0 0" xyz="-0.400215 0.351556 0.072882"/>
    <parent link="base_link"/>
    <child link="wheel_back_left_1"/>
    <axis xyz="0.0 -1.0 -0.0"/>
  </joint>
  <joint name="Rigid26" type="fixed">
    <origin rpy="0 0 0" xyz="-0.242882 -0.039266 0.283202"/>
    <parent link="base_link"/>
    <child link="nylon_platform_1"/>
  </joint>
  <joint name="arm_base_joint" type="continuous">
    <origin rpy="0 0 0" xyz="-0.075 0.0 0.18"/>
    <parent link="arm_base_1"/>
    <child link="base_turnable_1"/>
    <axis xyz="-0.0 0.0 -1.0"/>
  </joint>
  <joint name="Rigid28" type="fixed">
    <origin rpy="0 0 0" xyz="0.09 -0.04 0.085"/>
    <parent link="base_turnable_1"/>
    <child link="NEMA_34_1"/>
  </joint>
  <!--
<joint name="camera_revolute" type="continuous">
  <origin rpy="0 0 0" xyz="0.005 0.09 0.629827"/>
  <parent link="base_turnable_1"/>
  <child link="RealSense_Camera_1"/>
  <axis xyz="-0.0 0.0 -1.0"/>
</joint>
-->
  <joint name="Rigid30" type="fixed">
    <origin rpy="0 0 0" xyz="-0.2 0.0 0.06"/>
    <parent link="arm_base_1"/>
    <child link="NEMA_24_1_1"/>
  </joint>
  <joint name="Rigid31" type="fixed">
    <origin rpy="0 0 0" xyz="0.514256 -0.039266 0.051064"/>
    <parent link="base_link"/>
    <child link="DistanceSensor_front_1"/>
  </joint>
  <joint name="Rigid32" type="fixed">
    <origin rpy="0 0 0" xyz="-0.004794 0.279784 0.048649"/>
    <parent link="base_link"/>
    <child link="DistanceSensor_left_1"/>
  </joint>
  <joint name="Rigid33" type="fixed">
    <origin rpy="0 0 0" xyz="-0.004794 -0.358316 0.048649"/>
    <parent link="base_link"/>
    <child link="DistanceSensor_right_1"/>
  </joint>
  <joint name="Rigid34" type="fixed">
    <origin rpy="0 0 0" xyz="-0.523844 -0.039266 0.051064"/>
    <parent link="base_link"/>
    <child link="DistanceSensor_back_1"/>
  </joint>
</robot>

